
2020-08-27 16:15:56
FieldError("Cannot resolve keyword 'applydate' into field. Choices are: applyDate, applydeptid, applydeptname, applyerid, applyername, applyremark, autoid, batchno, caunit, checkamount, checkerid, checkername, checkgist, chkid, chkname, ciid, conclusion, createdate, expireddate, ittype, labtype, mbatchno, nosub, package, paperno, papertype, producer, remark, reportdate, reportdeptid, reportdeptname, reporterid, reportername, result, sampleamount, sampledate, samplerid, samplername, samplesource, sampleunit, seqid, spec, status, supplyer, warehousemanid, warehousemanname, warrantorid, warrantorname")
Traceback (most recent call last):
  File "D:\Anaconda3\envs\py3.8.5\lib\site-packages\django\db\models\sql\query.py", line 1863, in add_fields
    join_info = self.setup_joins(name.split(LOOKUP_SEP), opts, alias, allow_many=allow_m2m)
  File "D:\Anaconda3\envs\py3.8.5\lib\site-packages\django\db\models\sql\query.py", line 1565, in setup_joins
    path, final_field, targets, rest = self.names_to_path(
  File "D:\Anaconda3\envs\py3.8.5\lib\site-packages\django\db\models\sql\query.py", line 1481, in names_to_path
    raise FieldError("Cannot resolve keyword '%s' into field. "
django.core.exceptions.FieldError: Cannot resolve keyword 'applydate' into field. Choices are: applyDate, applydeptid, applydeptname, applyerid, applyername, applyremark, autoid, batchno, caunit, checkamount, checkerid, checkername, checkgist, chkid, chkname, ciid, conclusion, createdate, expireddate, ittype, labtype, mbatchno, nosub, package, paperno, papertype, producer, remark, reportdate, reportdeptid, reportdeptname, reporterid, reportername, result, sampleamount, sampledate, samplerid, samplername, samplesource, sampleunit, seqid, spec, status, supplyer, warehousemanid, warehousemanname, warrantorid, warrantorname

During handling of the above exception, another exception occurred:

Traceback (most recent call last):
  File "D:\pyproject\gmpsystem\labrecord\models\labmodel.py", line 19, in get_labrecord
    return res.values(*args)
  File "D:\Anaconda3\envs\py3.8.5\lib\site-packages\django\db\models\query.py", line 841, in values
    clone = self._values(*fields, **expressions)
  File "D:\Anaconda3\envs\py3.8.5\lib\site-packages\django\db\models\query.py", line 836, in _values
    clone.query.set_values(fields)
  File "D:\Anaconda3\envs\py3.8.5\lib\site-packages\django\db\models\sql\query.py", line 2172, in set_values
    self.add_fields(field_names, True)
  File "D:\Anaconda3\envs\py3.8.5\lib\site-packages\django\db\models\sql\query.py", line 1885, in add_fields
    raise FieldError("Cannot resolve keyword %r into field. "
django.core.exceptions.FieldError: Cannot resolve keyword 'applydate' into field. Choices are: applyDate, applydeptid, applydeptname, applyerid, applyername, applyremark, autoid, batchno, caunit, checkamount, checkerid, checkername, checkgist, chkid, chkname, ciid, conclusion, createdate, expireddate, ittype, labtype, mbatchno, nosub, package, paperno, papertype, producer, remark, reportdate, reportdeptid, reportdeptname, reporterid, reportername, result, sampleamount, sampledate, samplerid, samplername, samplesource, sampleunit, seqid, spec, status, supplyer, warehousemanid, warehousemanname, warrantorid, warrantorname

获取检验记录时出错
chkid
args=["chkname", "spec", "package", "applydate", "sampleamount", "sampleunit", "sampledate", "samplesource", "checkamount", "caunit", "batchno", "mbatchno", "supplyer", "producer", "paperno", "reportdate", "checkgist", "reporterid", "reportername", "checkerid", "checkername", "warrantorid", "warrantorname", "result", "conclusion"]
kwargs={"autoid": 7}
--------------------