
2020-08-31 15:44:52
TypeError("Field 'autoid' expected a number but got {'kind': 2, 'scid': 3538, 'title': '微信截图_20200831110225.png', 'creatorid': '001', 'creatorname': 'sys02', 'createdate': datetime.date(2020, 8, 31)}.")
Traceback (most recent call last):
  File "D:\Anaconda3\envs\py3.8.5\lib\site-packages\django\db\models\fields\__init__.py", line 1774, in get_prep_value
    return int(value)
TypeError: int() argument must be a string, a bytes-like object or a number, not 'dict'

The above exception was the direct cause of the following exception:

Traceback (most recent call last):
  File "D:\pyproject\gmpsystem\imageslib\imagesmodel.py", line 48, in update_rela
    return Relativepictures.objects.filter(autoid=autoid).update(
  File "D:\Anaconda3\envs\py3.8.5\lib\site-packages\django\db\models\manager.py", line 85, in manager_method
    return getattr(self.get_queryset(), name)(*args, **kwargs)
  File "D:\Anaconda3\envs\py3.8.5\lib\site-packages\django\db\models\query.py", line 942, in filter
    return self._filter_or_exclude(False, *args, **kwargs)
  File "D:\Anaconda3\envs\py3.8.5\lib\site-packages\django\db\models\query.py", line 962, in _filter_or_exclude
    clone._filter_or_exclude_inplace(negate, *args, **kwargs)
  File "D:\Anaconda3\envs\py3.8.5\lib\site-packages\django\db\models\query.py", line 969, in _filter_or_exclude_inplace
    self._query.add_q(Q(*args, **kwargs))
  File "D:\Anaconda3\envs\py3.8.5\lib\site-packages\django\db\models\sql\query.py", line 1358, in add_q
    clause, _ = self._add_q(q_object, self.used_aliases)
  File "D:\Anaconda3\envs\py3.8.5\lib\site-packages\django\db\models\sql\query.py", line 1377, in _add_q
    child_clause, needed_inner = self.build_filter(
  File "D:\Anaconda3\envs\py3.8.5\lib\site-packages\django\db\models\sql\query.py", line 1319, in build_filter
    condition = self.build_lookup(lookups, col, value)
  File "D:\Anaconda3\envs\py3.8.5\lib\site-packages\django\db\models\sql\query.py", line 1165, in build_lookup
    lookup = lookup_class(lhs, rhs)
  File "D:\Anaconda3\envs\py3.8.5\lib\site-packages\django\db\models\lookups.py", line 24, in __init__
    self.rhs = self.get_prep_lookup()
  File "D:\Anaconda3\envs\py3.8.5\lib\site-packages\django\db\models\lookups.py", line 74, in get_prep_lookup
    return self.lhs.output_field.get_prep_value(self.rhs)
  File "D:\Anaconda3\envs\py3.8.5\lib\site-packages\django\db\models\fields\__init__.py", line 1776, in get_prep_value
    raise e.__class__(
TypeError: Field 'autoid' expected a number but got {'kind': 2, 'scid': 3538, 'title': '微信截图_20200831110225.png', 'creatorid': '001', 'creatorname': 'sys02', 'createdate': datetime.date(2020, 8, 31)}.

更新图片关系出错
{'kind': 2, 'scid': 3538, 'title': '微信截图_20200831110225.png', 'creatorid': '001', 'creatorname': 'sys02', 'createdate': datetime.date(2020, 8, 31)}
args=[{"img": null, "ext": "png"}, 0, 0]
--------------------