
2020-08-19 09:48:09
IntegrityError(1048, "Column 'StuffType' cannot be null")
Traceback (most recent call last):
  File "D:\Anaconda3\envs\lib\site-packages\django\db\backends\utils.py", line 86, in _execute
    return self.cursor.execute(sql, params)
  File "D:\Anaconda3\envs\lib\site-packages\django\db\backends\mysql\base.py", line 75, in execute
    return self.cursor.execute(query, args)
  File "D:\Anaconda3\envs\lib\site-packages\pymysql\cursors.py", line 170, in execute
    result = self._query(query)
  File "D:\Anaconda3\envs\lib\site-packages\pymysql\cursors.py", line 328, in _query
    conn.query(q)
  File "D:\Anaconda3\envs\lib\site-packages\pymysql\connections.py", line 517, in query
    self._affected_rows = self._read_query_result(unbuffered=unbuffered)
  File "D:\Anaconda3\envs\lib\site-packages\pymysql\connections.py", line 732, in _read_query_result
    result.read()
  File "D:\Anaconda3\envs\lib\site-packages\pymysql\connections.py", line 1075, in read
    first_packet = self.connection._read_packet()
  File "D:\Anaconda3\envs\lib\site-packages\pymysql\connections.py", line 684, in _read_packet
    packet.check_error()
  File "D:\Anaconda3\envs\lib\site-packages\pymysql\protocol.py", line 220, in check_error
    err.raise_mysql_exception(self._data)
  File "D:\Anaconda3\envs\lib\site-packages\pymysql\err.py", line 109, in raise_mysql_exception
    raise errorclass(errno, errval)
pymysql.err.IntegrityError: (1048, "Column 'StuffType' cannot be null")

The above exception was the direct cause of the following exception:

Traceback (most recent call last):
  File "d:\pyproject\GMPsystem\warehouse\models\warehousemodel.py", line 78, in update_stuffrepository_amount
    WarehouseModel.update_productstuff(**item)
  File "d:\pyproject\GMPsystem\warehouse\models\warehousemodel.py", line 54, in update_productstuff
    return Productstuff.objects.create(**kwargs)
  File "D:\Anaconda3\envs\lib\site-packages\django\db\models\manager.py", line 82, in manager_method
    return getattr(self.get_queryset(), name)(*args, **kwargs)
  File "D:\Anaconda3\envs\lib\site-packages\django\db\models\query.py", line 433, in create
    obj.save(force_insert=True, using=self.db)
  File "D:\Anaconda3\envs\lib\site-packages\django\db\models\base.py", line 746, in save
    force_update=force_update, update_fields=update_fields)
  File "D:\Anaconda3\envs\lib\site-packages\django\db\models\base.py", line 784, in save_base
    force_update, using, update_fields,
  File "D:\Anaconda3\envs\lib\site-packages\django\db\models\base.py", line 887, in _save_table
    results = self._do_insert(cls._base_manager, using, fields, returning_fields, raw)
  File "D:\Anaconda3\envs\lib\site-packages\django\db\models\base.py", line 926, in _do_insert
    using=using, raw=raw,
  File "D:\Anaconda3\envs\lib\site-packages\django\db\models\manager.py", line 82, in manager_method
    return getattr(self.get_queryset(), name)(*args, **kwargs)
  File "D:\Anaconda3\envs\lib\site-packages\django\db\models\query.py", line 1204, in _insert
    return query.get_compiler(using=using).execute_sql(returning_fields)
  File "D:\Anaconda3\envs\lib\site-packages\django\db\models\sql\compiler.py", line 1391, in execute_sql
    cursor.execute(sql, params)
  File "D:\Anaconda3\envs\lib\site-packages\django\db\backends\utils.py", line 100, in execute
    return super().execute(sql, params)
  File "D:\Anaconda3\envs\lib\site-packages\django\db\backends\utils.py", line 68, in execute
    return self._execute_with_wrappers(sql, params, many=False, executor=self._execute)
  File "D:\Anaconda3\envs\lib\site-packages\django\db\backends\utils.py", line 77, in _execute_with_wrappers
    return executor(sql, params, many, context)
  File "D:\Anaconda3\envs\lib\site-packages\django\db\backends\utils.py", line 86, in _execute
    return self.cursor.execute(sql, params)
  File "D:\Anaconda3\envs\lib\site-packages\django\db\utils.py", line 90, in __exit__
    raise dj_exc_value.with_traceback(traceback) from exc_value
  File "D:\Anaconda3\envs\lib\site-packages\django\db\backends\utils.py", line 86, in _execute
    return self.cursor.execute(sql, params)
  File "D:\Anaconda3\envs\lib\site-packages\django\db\backends\mysql\base.py", line 75, in execute
    return self.cursor.execute(query, args)
  File "D:\Anaconda3\envs\lib\site-packages\pymysql\cursors.py", line 170, in execute
    result = self._query(query)
  File "D:\Anaconda3\envs\lib\site-packages\pymysql\cursors.py", line 328, in _query
    conn.query(q)
  File "D:\Anaconda3\envs\lib\site-packages\pymysql\connections.py", line 517, in query
    self._affected_rows = self._read_query_result(unbuffered=unbuffered)
  File "D:\Anaconda3\envs\lib\site-packages\pymysql\connections.py", line 732, in _read_query_result
    result.read()
  File "D:\Anaconda3\envs\lib\site-packages\pymysql\connections.py", line 1075, in read
    first_packet = self.connection._read_packet()
  File "D:\Anaconda3\envs\lib\site-packages\pymysql\connections.py", line 684, in _read_packet
    packet.check_error()
  File "D:\Anaconda3\envs\lib\site-packages\pymysql\protocol.py", line 220, in check_error
    err.raise_mysql_exception(self._data)
  File "D:\Anaconda3\envs\lib\site-packages\pymysql\err.py", line 109, in raise_mysql_exception
    raise errorclass(errno, errval)
django.db.utils.IntegrityError: (1048, "Column 'StuffType' cannot be null")

更新物料库存数量出错
({'srid': '1824', 'presamount': Decimal('93'), 'presunit': 'ml', 'pracamount': Decimal('108'), 'pracunit': 'ml', 'drawamount': Decimal('110'), 'drawunit': 'ml', 'precision': 0, 'sdpid': 6808, 'ppid': 36}, {'srid': '1759', 'presamount': Decimal('30.0000'), 'presunit': 'g', 'pracamount': Decimal('15.0000'), 'pracunit': 'g', 'drawamount': Decimal('15.3000'), 'drawunit': 'g', 'precision': 4, 'sdpid': 6808, 'ppid': 36})
--------------------
2020-08-19 09:52:17
IntegrityError(1048, "Column 'StuffType' cannot be null")
Traceback (most recent call last):
  File "D:\Anaconda3\envs\lib\site-packages\django\db\backends\utils.py", line 86, in _execute
    return self.cursor.execute(sql, params)
  File "D:\Anaconda3\envs\lib\site-packages\django\db\backends\mysql\base.py", line 75, in execute
    return self.cursor.execute(query, args)
  File "D:\Anaconda3\envs\lib\site-packages\pymysql\cursors.py", line 170, in execute
    result = self._query(query)
  File "D:\Anaconda3\envs\lib\site-packages\pymysql\cursors.py", line 328, in _query
    conn.query(q)
  File "D:\Anaconda3\envs\lib\site-packages\pymysql\connections.py", line 517, in query
    self._affected_rows = self._read_query_result(unbuffered=unbuffered)
  File "D:\Anaconda3\envs\lib\site-packages\pymysql\connections.py", line 732, in _read_query_result
    result.read()
  File "D:\Anaconda3\envs\lib\site-packages\pymysql\connections.py", line 1075, in read
    first_packet = self.connection._read_packet()
  File "D:\Anaconda3\envs\lib\site-packages\pymysql\connections.py", line 684, in _read_packet
    packet.check_error()
  File "D:\Anaconda3\envs\lib\site-packages\pymysql\protocol.py", line 220, in check_error
    err.raise_mysql_exception(self._data)
  File "D:\Anaconda3\envs\lib\site-packages\pymysql\err.py", line 109, in raise_mysql_exception
    raise errorclass(errno, errval)
pymysql.err.IntegrityError: (1048, "Column 'StuffType' cannot be null")

The above exception was the direct cause of the following exception:

Traceback (most recent call last):
  File "d:\pyproject\GMPsystem\warehouse\models\warehousemodel.py", line 78, in update_stuffrepository_amount
    WarehouseModel.update_productstuff(**item)
  File "d:\pyproject\GMPsystem\warehouse\models\warehousemodel.py", line 54, in update_productstuff
    return Productstuff.objects.create(**kwargs)
  File "D:\Anaconda3\envs\lib\site-packages\django\db\models\manager.py", line 82, in manager_method
    return getattr(self.get_queryset(), name)(*args, **kwargs)
  File "D:\Anaconda3\envs\lib\site-packages\django\db\models\query.py", line 433, in create
    obj.save(force_insert=True, using=self.db)
  File "D:\Anaconda3\envs\lib\site-packages\django\db\models\base.py", line 746, in save
    force_update=force_update, update_fields=update_fields)
  File "D:\Anaconda3\envs\lib\site-packages\django\db\models\base.py", line 784, in save_base
    force_update, using, update_fields,
  File "D:\Anaconda3\envs\lib\site-packages\django\db\models\base.py", line 887, in _save_table
    results = self._do_insert(cls._base_manager, using, fields, returning_fields, raw)
  File "D:\Anaconda3\envs\lib\site-packages\django\db\models\base.py", line 926, in _do_insert
    using=using, raw=raw,
  File "D:\Anaconda3\envs\lib\site-packages\django\db\models\manager.py", line 82, in manager_method
    return getattr(self.get_queryset(), name)(*args, **kwargs)
  File "D:\Anaconda3\envs\lib\site-packages\django\db\models\query.py", line 1204, in _insert
    return query.get_compiler(using=using).execute_sql(returning_fields)
  File "D:\Anaconda3\envs\lib\site-packages\django\db\models\sql\compiler.py", line 1391, in execute_sql
    cursor.execute(sql, params)
  File "D:\Anaconda3\envs\lib\site-packages\django\db\backends\utils.py", line 100, in execute
    return super().execute(sql, params)
  File "D:\Anaconda3\envs\lib\site-packages\django\db\backends\utils.py", line 68, in execute
    return self._execute_with_wrappers(sql, params, many=False, executor=self._execute)
  File "D:\Anaconda3\envs\lib\site-packages\django\db\backends\utils.py", line 77, in _execute_with_wrappers
    return executor(sql, params, many, context)
  File "D:\Anaconda3\envs\lib\site-packages\django\db\backends\utils.py", line 86, in _execute
    return self.cursor.execute(sql, params)
  File "D:\Anaconda3\envs\lib\site-packages\django\db\utils.py", line 90, in __exit__
    raise dj_exc_value.with_traceback(traceback) from exc_value
  File "D:\Anaconda3\envs\lib\site-packages\django\db\backends\utils.py", line 86, in _execute
    return self.cursor.execute(sql, params)
  File "D:\Anaconda3\envs\lib\site-packages\django\db\backends\mysql\base.py", line 75, in execute
    return self.cursor.execute(query, args)
  File "D:\Anaconda3\envs\lib\site-packages\pymysql\cursors.py", line 170, in execute
    result = self._query(query)
  File "D:\Anaconda3\envs\lib\site-packages\pymysql\cursors.py", line 328, in _query
    conn.query(q)
  File "D:\Anaconda3\envs\lib\site-packages\pymysql\connections.py", line 517, in query
    self._affected_rows = self._read_query_result(unbuffered=unbuffered)
  File "D:\Anaconda3\envs\lib\site-packages\pymysql\connections.py", line 732, in _read_query_result
    result.read()
  File "D:\Anaconda3\envs\lib\site-packages\pymysql\connections.py", line 1075, in read
    first_packet = self.connection._read_packet()
  File "D:\Anaconda3\envs\lib\site-packages\pymysql\connections.py", line 684, in _read_packet
    packet.check_error()
  File "D:\Anaconda3\envs\lib\site-packages\pymysql\protocol.py", line 220, in check_error
    err.raise_mysql_exception(self._data)
  File "D:\Anaconda3\envs\lib\site-packages\pymysql\err.py", line 109, in raise_mysql_exception
    raise errorclass(errno, errval)
django.db.utils.IntegrityError: (1048, "Column 'StuffType' cannot be null")

更新物料库存数量出错
({'srid': '1824', 'presamount': Decimal('93'), 'presunit': 'ml', 'pracamount': Decimal('108'), 'pracunit': 'ml', 'drawamount': Decimal('110'), 'drawunit': 'ml', 'precision': 0, 'sdpid': 6808, 'ppid': 36}, {'srid': '1759', 'presamount': Decimal('30.0000'), 'presunit': 'g', 'pracamount': Decimal('15.0000'), 'pracunit': 'g', 'drawamount': Decimal('15.3000'), 'drawunit': 'g', 'precision': 4, 'sdpid': 6808, 'ppid': 36})
--------------------
2020-08-19 09:58:14
IntegrityError(1048, "Column 'Price' cannot be null")
Traceback (most recent call last):
  File "D:\Anaconda3\envs\lib\site-packages\django\db\backends\utils.py", line 86, in _execute
    return self.cursor.execute(sql, params)
  File "D:\Anaconda3\envs\lib\site-packages\django\db\backends\mysql\base.py", line 75, in execute
    return self.cursor.execute(query, args)
  File "D:\Anaconda3\envs\lib\site-packages\pymysql\cursors.py", line 170, in execute
    result = self._query(query)
  File "D:\Anaconda3\envs\lib\site-packages\pymysql\cursors.py", line 328, in _query
    conn.query(q)
  File "D:\Anaconda3\envs\lib\site-packages\pymysql\connections.py", line 517, in query
    self._affected_rows = self._read_query_result(unbuffered=unbuffered)
  File "D:\Anaconda3\envs\lib\site-packages\pymysql\connections.py", line 732, in _read_query_result
    result.read()
  File "D:\Anaconda3\envs\lib\site-packages\pymysql\connections.py", line 1075, in read
    first_packet = self.connection._read_packet()
  File "D:\Anaconda3\envs\lib\site-packages\pymysql\connections.py", line 684, in _read_packet
    packet.check_error()
  File "D:\Anaconda3\envs\lib\site-packages\pymysql\protocol.py", line 220, in check_error
    err.raise_mysql_exception(self._data)
  File "D:\Anaconda3\envs\lib\site-packages\pymysql\err.py", line 109, in raise_mysql_exception
    raise errorclass(errno, errval)
pymysql.err.IntegrityError: (1048, "Column 'Price' cannot be null")

The above exception was the direct cause of the following exception:

Traceback (most recent call last):
  File "d:\pyproject\GMPsystem\warehouse\models\warehousemodel.py", line 78, in update_stuffrepository_amount
    WarehouseModel.update_productstuff(**item)
  File "d:\pyproject\GMPsystem\warehouse\models\warehousemodel.py", line 54, in update_productstuff
    return Productstuff.objects.create(**kwargs)
  File "D:\Anaconda3\envs\lib\site-packages\django\db\models\manager.py", line 82, in manager_method
    return getattr(self.get_queryset(), name)(*args, **kwargs)
  File "D:\Anaconda3\envs\lib\site-packages\django\db\models\query.py", line 433, in create
    obj.save(force_insert=True, using=self.db)
  File "D:\Anaconda3\envs\lib\site-packages\django\db\models\base.py", line 746, in save
    force_update=force_update, update_fields=update_fields)
  File "D:\Anaconda3\envs\lib\site-packages\django\db\models\base.py", line 784, in save_base
    force_update, using, update_fields,
  File "D:\Anaconda3\envs\lib\site-packages\django\db\models\base.py", line 887, in _save_table
    results = self._do_insert(cls._base_manager, using, fields, returning_fields, raw)
  File "D:\Anaconda3\envs\lib\site-packages\django\db\models\base.py", line 926, in _do_insert
    using=using, raw=raw,
  File "D:\Anaconda3\envs\lib\site-packages\django\db\models\manager.py", line 82, in manager_method
    return getattr(self.get_queryset(), name)(*args, **kwargs)
  File "D:\Anaconda3\envs\lib\site-packages\django\db\models\query.py", line 1204, in _insert
    return query.get_compiler(using=using).execute_sql(returning_fields)
  File "D:\Anaconda3\envs\lib\site-packages\django\db\models\sql\compiler.py", line 1391, in execute_sql
    cursor.execute(sql, params)
  File "D:\Anaconda3\envs\lib\site-packages\django\db\backends\utils.py", line 100, in execute
    return super().execute(sql, params)
  File "D:\Anaconda3\envs\lib\site-packages\django\db\backends\utils.py", line 68, in execute
    return self._execute_with_wrappers(sql, params, many=False, executor=self._execute)
  File "D:\Anaconda3\envs\lib\site-packages\django\db\backends\utils.py", line 77, in _execute_with_wrappers
    return executor(sql, params, many, context)
  File "D:\Anaconda3\envs\lib\site-packages\django\db\backends\utils.py", line 86, in _execute
    return self.cursor.execute(sql, params)
  File "D:\Anaconda3\envs\lib\site-packages\django\db\utils.py", line 90, in __exit__
    raise dj_exc_value.with_traceback(traceback) from exc_value
  File "D:\Anaconda3\envs\lib\site-packages\django\db\backends\utils.py", line 86, in _execute
    return self.cursor.execute(sql, params)
  File "D:\Anaconda3\envs\lib\site-packages\django\db\backends\mysql\base.py", line 75, in execute
    return self.cursor.execute(query, args)
  File "D:\Anaconda3\envs\lib\site-packages\pymysql\cursors.py", line 170, in execute
    result = self._query(query)
  File "D:\Anaconda3\envs\lib\site-packages\pymysql\cursors.py", line 328, in _query
    conn.query(q)
  File "D:\Anaconda3\envs\lib\site-packages\pymysql\connections.py", line 517, in query
    self._affected_rows = self._read_query_result(unbuffered=unbuffered)
  File "D:\Anaconda3\envs\lib\site-packages\pymysql\connections.py", line 732, in _read_query_result
    result.read()
  File "D:\Anaconda3\envs\lib\site-packages\pymysql\connections.py", line 1075, in read
    first_packet = self.connection._read_packet()
  File "D:\Anaconda3\envs\lib\site-packages\pymysql\connections.py", line 684, in _read_packet
    packet.check_error()
  File "D:\Anaconda3\envs\lib\site-packages\pymysql\protocol.py", line 220, in check_error
    err.raise_mysql_exception(self._data)
  File "D:\Anaconda3\envs\lib\site-packages\pymysql\err.py", line 109, in raise_mysql_exception
    raise errorclass(errno, errval)
django.db.utils.IntegrityError: (1048, "Column 'Price' cannot be null")

更新物料库存数量出错
({'srid': '1824', 'presamount': Decimal('93'), 'presunit': 'ml', 'pracamount': Decimal('108'), 'pracunit': 'ml', 'drawamount': Decimal('110'), 'drawunit': 'ml', 'loss': '0.00', 'precision': 0, 'stuffid': '04030002', 'stuffname': '酒石酸泰万菌素', 'stufftype': 0, 'stuffkind': '酒石酸泰万菌素', 'spec': '10kg/桶', 'package': '10kg/桶', 'producer': '内蒙中牧生物药业有限公司', 'batchno': '01', 'lrid': 0, 'content': Decimal('88.00'), 'cunit': '', 'impurity': Decimal('0.00'), 'rdensity': Decimal('1.0000'), 'mbatchno': '01', 'sdpid': 6808, 'ppid': 36}, {'srid': '1759', 'presamount': Decimal('30.0000'), 'presunit': 'g', 'pracamount': Decimal('15.0000'), 'pracunit': 'g', 'drawamount': Decimal('15.3000'), 'drawunit': 'g', 'loss': '0.00', 'precision': 4, 'stuffid': '0408034', 'stuffname': '无水葡萄糖', 'stufftype': 1, 'stuffkind': '无水葡萄糖', 'spec': '25kg/包', 'package': '25kg/包', 'producer': '西王药业有限公司', 'batchno': '20190901', 'lrid': 2939, 'content': Decimal('100.00'), 'cunit': '', 'impurity': Decimal('5.00'), 'rdensity': Decimal('1.3000'), 'mbatchno': '20190630XA', 'sdpid': 6808, 'ppid': 36})
--------------------
2020-08-19 09:59:48
IntegrityError(1048, "Column 'Price' cannot be null")
Traceback (most recent call last):
  File "D:\Anaconda3\envs\lib\site-packages\django\db\backends\utils.py", line 86, in _execute
    return self.cursor.execute(sql, params)
  File "D:\Anaconda3\envs\lib\site-packages\django\db\backends\mysql\base.py", line 75, in execute
    return self.cursor.execute(query, args)
  File "D:\Anaconda3\envs\lib\site-packages\pymysql\cursors.py", line 170, in execute
    result = self._query(query)
  File "D:\Anaconda3\envs\lib\site-packages\pymysql\cursors.py", line 328, in _query
    conn.query(q)
  File "D:\Anaconda3\envs\lib\site-packages\pymysql\connections.py", line 517, in query
    self._affected_rows = self._read_query_result(unbuffered=unbuffered)
  File "D:\Anaconda3\envs\lib\site-packages\pymysql\connections.py", line 732, in _read_query_result
    result.read()
  File "D:\Anaconda3\envs\lib\site-packages\pymysql\connections.py", line 1075, in read
    first_packet = self.connection._read_packet()
  File "D:\Anaconda3\envs\lib\site-packages\pymysql\connections.py", line 684, in _read_packet
    packet.check_error()
  File "D:\Anaconda3\envs\lib\site-packages\pymysql\protocol.py", line 220, in check_error
    err.raise_mysql_exception(self._data)
  File "D:\Anaconda3\envs\lib\site-packages\pymysql\err.py", line 109, in raise_mysql_exception
    raise errorclass(errno, errval)
pymysql.err.IntegrityError: (1048, "Column 'Price' cannot be null")

The above exception was the direct cause of the following exception:

Traceback (most recent call last):
  File "d:\pyproject\GMPsystem\warehouse\models\warehousemodel.py", line 78, in update_stuffrepository_amount
    WarehouseModel.update_productstuff(**item)
  File "d:\pyproject\GMPsystem\warehouse\models\warehousemodel.py", line 54, in update_productstuff
    return Productstuff.objects.create(**kwargs)
  File "D:\Anaconda3\envs\lib\site-packages\django\db\models\manager.py", line 82, in manager_method
    return getattr(self.get_queryset(), name)(*args, **kwargs)
  File "D:\Anaconda3\envs\lib\site-packages\django\db\models\query.py", line 433, in create
    obj.save(force_insert=True, using=self.db)
  File "D:\Anaconda3\envs\lib\site-packages\django\db\models\base.py", line 746, in save
    force_update=force_update, update_fields=update_fields)
  File "D:\Anaconda3\envs\lib\site-packages\django\db\models\base.py", line 784, in save_base
    force_update, using, update_fields,
  File "D:\Anaconda3\envs\lib\site-packages\django\db\models\base.py", line 887, in _save_table
    results = self._do_insert(cls._base_manager, using, fields, returning_fields, raw)
  File "D:\Anaconda3\envs\lib\site-packages\django\db\models\base.py", line 926, in _do_insert
    using=using, raw=raw,
  File "D:\Anaconda3\envs\lib\site-packages\django\db\models\manager.py", line 82, in manager_method
    return getattr(self.get_queryset(), name)(*args, **kwargs)
  File "D:\Anaconda3\envs\lib\site-packages\django\db\models\query.py", line 1204, in _insert
    return query.get_compiler(using=using).execute_sql(returning_fields)
  File "D:\Anaconda3\envs\lib\site-packages\django\db\models\sql\compiler.py", line 1391, in execute_sql
    cursor.execute(sql, params)
  File "D:\Anaconda3\envs\lib\site-packages\django\db\backends\utils.py", line 100, in execute
    return super().execute(sql, params)
  File "D:\Anaconda3\envs\lib\site-packages\django\db\backends\utils.py", line 68, in execute
    return self._execute_with_wrappers(sql, params, many=False, executor=self._execute)
  File "D:\Anaconda3\envs\lib\site-packages\django\db\backends\utils.py", line 77, in _execute_with_wrappers
    return executor(sql, params, many, context)
  File "D:\Anaconda3\envs\lib\site-packages\django\db\backends\utils.py", line 86, in _execute
    return self.cursor.execute(sql, params)
  File "D:\Anaconda3\envs\lib\site-packages\django\db\utils.py", line 90, in __exit__
    raise dj_exc_value.with_traceback(traceback) from exc_value
  File "D:\Anaconda3\envs\lib\site-packages\django\db\backends\utils.py", line 86, in _execute
    return self.cursor.execute(sql, params)
  File "D:\Anaconda3\envs\lib\site-packages\django\db\backends\mysql\base.py", line 75, in execute
    return self.cursor.execute(query, args)
  File "D:\Anaconda3\envs\lib\site-packages\pymysql\cursors.py", line 170, in execute
    result = self._query(query)
  File "D:\Anaconda3\envs\lib\site-packages\pymysql\cursors.py", line 328, in _query
    conn.query(q)
  File "D:\Anaconda3\envs\lib\site-packages\pymysql\connections.py", line 517, in query
    self._affected_rows = self._read_query_result(unbuffered=unbuffered)
  File "D:\Anaconda3\envs\lib\site-packages\pymysql\connections.py", line 732, in _read_query_result
    result.read()
  File "D:\Anaconda3\envs\lib\site-packages\pymysql\connections.py", line 1075, in read
    first_packet = self.connection._read_packet()
  File "D:\Anaconda3\envs\lib\site-packages\pymysql\connections.py", line 684, in _read_packet
    packet.check_error()
  File "D:\Anaconda3\envs\lib\site-packages\pymysql\protocol.py", line 220, in check_error
    err.raise_mysql_exception(self._data)
  File "D:\Anaconda3\envs\lib\site-packages\pymysql\err.py", line 109, in raise_mysql_exception
    raise errorclass(errno, errval)
django.db.utils.IntegrityError: (1048, "Column 'Price' cannot be null")

更新物料库存数量出错
({'srid': '1824', 'presamount': Decimal('93'), 'presunit': 'ml', 'pracamount': Decimal('108'), 'pracunit': 'ml', 'drawamount': Decimal('110'), 'drawunit': 'ml', 'loss': '0.00', 'precision': 0, 'stuffid': '04030002', 'stuffname': '酒石酸泰万菌素', 'stufftype': 0, 'stuffkind': '酒石酸泰万菌素', 'spec': '10kg/桶', 'package': '10kg/桶', 'producer': '内蒙中牧生物药业有限公司', 'batchno': '01', 'lrid': 0, 'content': Decimal('88.00'), 'cunit': '', 'impurity': Decimal('0.00'), 'rdensity': Decimal('1.0000'), 'mbatchno': '01', 'sdpid': 6808, 'ppid': 36}, {'srid': '1759', 'presamount': Decimal('30.0000'), 'presunit': 'g', 'pracamount': Decimal('15.0000'), 'pracunit': 'g', 'drawamount': Decimal('15.3000'), 'drawunit': 'g', 'loss': '0.00', 'precision': 4, 'stuffid': '0408034', 'stuffname': '无水葡萄糖', 'stufftype': 1, 'stuffkind': '无水葡萄糖', 'spec': '25kg/包', 'package': '25kg/包', 'producer': '西王药业有限公司', 'batchno': '20190901', 'lrid': 2939, 'content': Decimal('100.00'), 'cunit': '', 'impurity': Decimal('5.00'), 'rdensity': Decimal('1.3000'), 'mbatchno': '20190630XA', 'sdpid': 6808, 'ppid': 36})
--------------------
2020-08-19 10:00:51
IntegrityError(1048, "Column 'Water' cannot be null")
Traceback (most recent call last):
  File "D:\Anaconda3\envs\lib\site-packages\django\db\backends\utils.py", line 86, in _execute
    return self.cursor.execute(sql, params)
  File "D:\Anaconda3\envs\lib\site-packages\django\db\backends\mysql\base.py", line 75, in execute
    return self.cursor.execute(query, args)
  File "D:\Anaconda3\envs\lib\site-packages\pymysql\cursors.py", line 170, in execute
    result = self._query(query)
  File "D:\Anaconda3\envs\lib\site-packages\pymysql\cursors.py", line 328, in _query
    conn.query(q)
  File "D:\Anaconda3\envs\lib\site-packages\pymysql\connections.py", line 517, in query
    self._affected_rows = self._read_query_result(unbuffered=unbuffered)
  File "D:\Anaconda3\envs\lib\site-packages\pymysql\connections.py", line 732, in _read_query_result
    result.read()
  File "D:\Anaconda3\envs\lib\site-packages\pymysql\connections.py", line 1075, in read
    first_packet = self.connection._read_packet()
  File "D:\Anaconda3\envs\lib\site-packages\pymysql\connections.py", line 684, in _read_packet
    packet.check_error()
  File "D:\Anaconda3\envs\lib\site-packages\pymysql\protocol.py", line 220, in check_error
    err.raise_mysql_exception(self._data)
  File "D:\Anaconda3\envs\lib\site-packages\pymysql\err.py", line 109, in raise_mysql_exception
    raise errorclass(errno, errval)
pymysql.err.IntegrityError: (1048, "Column 'Water' cannot be null")

The above exception was the direct cause of the following exception:

Traceback (most recent call last):
  File "d:\pyproject\GMPsystem\warehouse\models\warehousemodel.py", line 78, in update_stuffrepository_amount
    WarehouseModel.update_productstuff(**item)
  File "d:\pyproject\GMPsystem\warehouse\models\warehousemodel.py", line 54, in update_productstuff
    return Productstuff.objects.create(**kwargs)
  File "D:\Anaconda3\envs\lib\site-packages\django\db\models\manager.py", line 82, in manager_method
    return getattr(self.get_queryset(), name)(*args, **kwargs)
  File "D:\Anaconda3\envs\lib\site-packages\django\db\models\query.py", line 433, in create
    obj.save(force_insert=True, using=self.db)
  File "D:\Anaconda3\envs\lib\site-packages\django\db\models\base.py", line 746, in save
    force_update=force_update, update_fields=update_fields)
  File "D:\Anaconda3\envs\lib\site-packages\django\db\models\base.py", line 784, in save_base
    force_update, using, update_fields,
  File "D:\Anaconda3\envs\lib\site-packages\django\db\models\base.py", line 887, in _save_table
    results = self._do_insert(cls._base_manager, using, fields, returning_fields, raw)
  File "D:\Anaconda3\envs\lib\site-packages\django\db\models\base.py", line 926, in _do_insert
    using=using, raw=raw,
  File "D:\Anaconda3\envs\lib\site-packages\django\db\models\manager.py", line 82, in manager_method
    return getattr(self.get_queryset(), name)(*args, **kwargs)
  File "D:\Anaconda3\envs\lib\site-packages\django\db\models\query.py", line 1204, in _insert
    return query.get_compiler(using=using).execute_sql(returning_fields)
  File "D:\Anaconda3\envs\lib\site-packages\django\db\models\sql\compiler.py", line 1391, in execute_sql
    cursor.execute(sql, params)
  File "D:\Anaconda3\envs\lib\site-packages\django\db\backends\utils.py", line 100, in execute
    return super().execute(sql, params)
  File "D:\Anaconda3\envs\lib\site-packages\django\db\backends\utils.py", line 68, in execute
    return self._execute_with_wrappers(sql, params, many=False, executor=self._execute)
  File "D:\Anaconda3\envs\lib\site-packages\django\db\backends\utils.py", line 77, in _execute_with_wrappers
    return executor(sql, params, many, context)
  File "D:\Anaconda3\envs\lib\site-packages\django\db\backends\utils.py", line 86, in _execute
    return self.cursor.execute(sql, params)
  File "D:\Anaconda3\envs\lib\site-packages\django\db\utils.py", line 90, in __exit__
    raise dj_exc_value.with_traceback(traceback) from exc_value
  File "D:\Anaconda3\envs\lib\site-packages\django\db\backends\utils.py", line 86, in _execute
    return self.cursor.execute(sql, params)
  File "D:\Anaconda3\envs\lib\site-packages\django\db\backends\mysql\base.py", line 75, in execute
    return self.cursor.execute(query, args)
  File "D:\Anaconda3\envs\lib\site-packages\pymysql\cursors.py", line 170, in execute
    result = self._query(query)
  File "D:\Anaconda3\envs\lib\site-packages\pymysql\cursors.py", line 328, in _query
    conn.query(q)
  File "D:\Anaconda3\envs\lib\site-packages\pymysql\connections.py", line 517, in query
    self._affected_rows = self._read_query_result(unbuffered=unbuffered)
  File "D:\Anaconda3\envs\lib\site-packages\pymysql\connections.py", line 732, in _read_query_result
    result.read()
  File "D:\Anaconda3\envs\lib\site-packages\pymysql\connections.py", line 1075, in read
    first_packet = self.connection._read_packet()
  File "D:\Anaconda3\envs\lib\site-packages\pymysql\connections.py", line 684, in _read_packet
    packet.check_error()
  File "D:\Anaconda3\envs\lib\site-packages\pymysql\protocol.py", line 220, in check_error
    err.raise_mysql_exception(self._data)
  File "D:\Anaconda3\envs\lib\site-packages\pymysql\err.py", line 109, in raise_mysql_exception
    raise errorclass(errno, errval)
django.db.utils.IntegrityError: (1048, "Column 'Water' cannot be null")

更新物料库存数量出错
({'srid': '1824', 'presamount': Decimal('93'), 'presunit': 'ml', 'pracamount': Decimal('108'), 'pracunit': 'ml', 'drawamount': Decimal('110'), 'drawunit': 'ml', 'loss': '0.00', 'precision': 0, 'stuffid': '04030002', 'stuffname': '酒石酸泰万菌素', 'stufftype': 0, 'stuffkind': '酒石酸泰万菌素', 'spec': '10kg/桶', 'package': '10kg/桶', 'producer': '内蒙中牧生物药业有限公司', 'batchno': '01', 'lrid': 0, 'content': Decimal('88.00'), 'cunit': '', 'impurity': Decimal('0.00'), 'rdensity': Decimal('1.0000'), 'mbatchno': '01', 'sdpid': 6808, 'ppid': 36}, {'srid': '1759', 'presamount': Decimal('30.0000'), 'presunit': 'g', 'pracamount': Decimal('15.0000'), 'pracunit': 'g', 'drawamount': Decimal('15.3000'), 'drawunit': 'g', 'loss': '0.00', 'precision': 4, 'stuffid': '0408034', 'stuffname': '无水葡萄糖', 'stufftype': 1, 'stuffkind': '无水葡萄糖', 'spec': '25kg/包', 'package': '25kg/包', 'producer': '西王药业有限公司', 'batchno': '20190901', 'lrid': 2939, 'content': Decimal('100.00'), 'cunit': '', 'impurity': Decimal('5.00'), 'rdensity': Decimal('1.3000'), 'mbatchno': '20190630XA', 'sdpid': 6808, 'ppid': 36})
--------------------
2020-08-19 10:01:23
IntegrityError(1048, "Column 'CheckAmount' cannot be null")
Traceback (most recent call last):
  File "D:\Anaconda3\envs\lib\site-packages\django\db\backends\utils.py", line 86, in _execute
    return self.cursor.execute(sql, params)
  File "D:\Anaconda3\envs\lib\site-packages\django\db\backends\mysql\base.py", line 75, in execute
    return self.cursor.execute(query, args)
  File "D:\Anaconda3\envs\lib\site-packages\pymysql\cursors.py", line 170, in execute
    result = self._query(query)
  File "D:\Anaconda3\envs\lib\site-packages\pymysql\cursors.py", line 328, in _query
    conn.query(q)
  File "D:\Anaconda3\envs\lib\site-packages\pymysql\connections.py", line 517, in query
    self._affected_rows = self._read_query_result(unbuffered=unbuffered)
  File "D:\Anaconda3\envs\lib\site-packages\pymysql\connections.py", line 732, in _read_query_result
    result.read()
  File "D:\Anaconda3\envs\lib\site-packages\pymysql\connections.py", line 1075, in read
    first_packet = self.connection._read_packet()
  File "D:\Anaconda3\envs\lib\site-packages\pymysql\connections.py", line 684, in _read_packet
    packet.check_error()
  File "D:\Anaconda3\envs\lib\site-packages\pymysql\protocol.py", line 220, in check_error
    err.raise_mysql_exception(self._data)
  File "D:\Anaconda3\envs\lib\site-packages\pymysql\err.py", line 109, in raise_mysql_exception
    raise errorclass(errno, errval)
pymysql.err.IntegrityError: (1048, "Column 'CheckAmount' cannot be null")

The above exception was the direct cause of the following exception:

Traceback (most recent call last):
  File "d:\pyproject\GMPsystem\warehouse\models\warehousemodel.py", line 78, in update_stuffrepository_amount
    WarehouseModel.update_productstuff(**item)
  File "d:\pyproject\GMPsystem\warehouse\models\warehousemodel.py", line 54, in update_productstuff
    return Productstuff.objects.create(**kwargs)
  File "D:\Anaconda3\envs\lib\site-packages\django\db\models\manager.py", line 82, in manager_method
    return getattr(self.get_queryset(), name)(*args, **kwargs)
  File "D:\Anaconda3\envs\lib\site-packages\django\db\models\query.py", line 433, in create
    obj.save(force_insert=True, using=self.db)
  File "D:\Anaconda3\envs\lib\site-packages\django\db\models\base.py", line 746, in save
    force_update=force_update, update_fields=update_fields)
  File "D:\Anaconda3\envs\lib\site-packages\django\db\models\base.py", line 784, in save_base
    force_update, using, update_fields,
  File "D:\Anaconda3\envs\lib\site-packages\django\db\models\base.py", line 887, in _save_table
    results = self._do_insert(cls._base_manager, using, fields, returning_fields, raw)
  File "D:\Anaconda3\envs\lib\site-packages\django\db\models\base.py", line 926, in _do_insert
    using=using, raw=raw,
  File "D:\Anaconda3\envs\lib\site-packages\django\db\models\manager.py", line 82, in manager_method
    return getattr(self.get_queryset(), name)(*args, **kwargs)
  File "D:\Anaconda3\envs\lib\site-packages\django\db\models\query.py", line 1204, in _insert
    return query.get_compiler(using=using).execute_sql(returning_fields)
  File "D:\Anaconda3\envs\lib\site-packages\django\db\models\sql\compiler.py", line 1391, in execute_sql
    cursor.execute(sql, params)
  File "D:\Anaconda3\envs\lib\site-packages\django\db\backends\utils.py", line 100, in execute
    return super().execute(sql, params)
  File "D:\Anaconda3\envs\lib\site-packages\django\db\backends\utils.py", line 68, in execute
    return self._execute_with_wrappers(sql, params, many=False, executor=self._execute)
  File "D:\Anaconda3\envs\lib\site-packages\django\db\backends\utils.py", line 77, in _execute_with_wrappers
    return executor(sql, params, many, context)
  File "D:\Anaconda3\envs\lib\site-packages\django\db\backends\utils.py", line 86, in _execute
    return self.cursor.execute(sql, params)
  File "D:\Anaconda3\envs\lib\site-packages\django\db\utils.py", line 90, in __exit__
    raise dj_exc_value.with_traceback(traceback) from exc_value
  File "D:\Anaconda3\envs\lib\site-packages\django\db\backends\utils.py", line 86, in _execute
    return self.cursor.execute(sql, params)
  File "D:\Anaconda3\envs\lib\site-packages\django\db\backends\mysql\base.py", line 75, in execute
    return self.cursor.execute(query, args)
  File "D:\Anaconda3\envs\lib\site-packages\pymysql\cursors.py", line 170, in execute
    result = self._query(query)
  File "D:\Anaconda3\envs\lib\site-packages\pymysql\cursors.py", line 328, in _query
    conn.query(q)
  File "D:\Anaconda3\envs\lib\site-packages\pymysql\connections.py", line 517, in query
    self._affected_rows = self._read_query_result(unbuffered=unbuffered)
  File "D:\Anaconda3\envs\lib\site-packages\pymysql\connections.py", line 732, in _read_query_result
    result.read()
  File "D:\Anaconda3\envs\lib\site-packages\pymysql\connections.py", line 1075, in read
    first_packet = self.connection._read_packet()
  File "D:\Anaconda3\envs\lib\site-packages\pymysql\connections.py", line 684, in _read_packet
    packet.check_error()
  File "D:\Anaconda3\envs\lib\site-packages\pymysql\protocol.py", line 220, in check_error
    err.raise_mysql_exception(self._data)
  File "D:\Anaconda3\envs\lib\site-packages\pymysql\err.py", line 109, in raise_mysql_exception
    raise errorclass(errno, errval)
django.db.utils.IntegrityError: (1048, "Column 'CheckAmount' cannot be null")

更新物料库存数量出错
({'srid': '1824', 'presamount': Decimal('93'), 'presunit': 'ml', 'pracamount': Decimal('108'), 'pracunit': 'ml', 'drawamount': Decimal('110'), 'drawunit': 'ml', 'loss': '0.00', 'precision': 0, 'stuffid': '04030002', 'stuffname': '酒石酸泰万菌素', 'stufftype': 0, 'stuffkind': '酒石酸泰万菌素', 'spec': '10kg/桶', 'package': '10kg/桶', 'producer': '内蒙中牧生物药业有限公司', 'batchno': '01', 'lrid': 0, 'content': Decimal('88.00'), 'cunit': '', 'water': Decimal('2.00'), 'impurity': Decimal('0.00'), 'rdensity': Decimal('1.0000'), 'mbatchno': '01', 'sdpid': 6808, 'ppid': 36}, {'srid': '1759', 'presamount': Decimal('30.0000'), 'presunit': 'g', 'pracamount': Decimal('15.0000'), 'pracunit': 'g', 'drawamount': Decimal('15.3000'), 'drawunit': 'g', 'loss': '0.00', 'precision': 4, 'stuffid': '0408034', 'stuffname': '无水葡萄糖', 'stufftype': 1, 'stuffkind': '无水葡萄糖', 'spec': '25kg/包', 'package': '25kg/包', 'producer': '西王药业有限公司', 'batchno': '20190901', 'lrid': 2939, 'content': Decimal('100.00'), 'cunit': '', 'water': Decimal('0.10'), 'impurity': Decimal('5.00'), 'rdensity': Decimal('1.3000'), 'mbatchno': '20190630XA', 'sdpid': 6808, 'ppid': 36})
--------------------
2020-08-19 10:02:39
IntegrityError(1048, "Column 'RealAmount' cannot be null")
Traceback (most recent call last):
  File "D:\Anaconda3\envs\lib\site-packages\django\db\backends\utils.py", line 86, in _execute
    return self.cursor.execute(sql, params)
  File "D:\Anaconda3\envs\lib\site-packages\django\db\backends\mysql\base.py", line 75, in execute
    return self.cursor.execute(query, args)
  File "D:\Anaconda3\envs\lib\site-packages\pymysql\cursors.py", line 170, in execute
    result = self._query(query)
  File "D:\Anaconda3\envs\lib\site-packages\pymysql\cursors.py", line 328, in _query
    conn.query(q)
  File "D:\Anaconda3\envs\lib\site-packages\pymysql\connections.py", line 517, in query
    self._affected_rows = self._read_query_result(unbuffered=unbuffered)
  File "D:\Anaconda3\envs\lib\site-packages\pymysql\connections.py", line 732, in _read_query_result
    result.read()
  File "D:\Anaconda3\envs\lib\site-packages\pymysql\connections.py", line 1075, in read
    first_packet = self.connection._read_packet()
  File "D:\Anaconda3\envs\lib\site-packages\pymysql\connections.py", line 684, in _read_packet
    packet.check_error()
  File "D:\Anaconda3\envs\lib\site-packages\pymysql\protocol.py", line 220, in check_error
    err.raise_mysql_exception(self._data)
  File "D:\Anaconda3\envs\lib\site-packages\pymysql\err.py", line 109, in raise_mysql_exception
    raise errorclass(errno, errval)
pymysql.err.IntegrityError: (1048, "Column 'RealAmount' cannot be null")

The above exception was the direct cause of the following exception:

Traceback (most recent call last):
  File "d:\pyproject\GMPsystem\warehouse\models\warehousemodel.py", line 78, in update_stuffrepository_amount
    WarehouseModel.update_productstuff(**item)
  File "d:\pyproject\GMPsystem\warehouse\models\warehousemodel.py", line 54, in update_productstuff
    return Productstuff.objects.create(**kwargs)
  File "D:\Anaconda3\envs\lib\site-packages\django\db\models\manager.py", line 82, in manager_method
    return getattr(self.get_queryset(), name)(*args, **kwargs)
  File "D:\Anaconda3\envs\lib\site-packages\django\db\models\query.py", line 433, in create
    obj.save(force_insert=True, using=self.db)
  File "D:\Anaconda3\envs\lib\site-packages\django\db\models\base.py", line 746, in save
    force_update=force_update, update_fields=update_fields)
  File "D:\Anaconda3\envs\lib\site-packages\django\db\models\base.py", line 784, in save_base
    force_update, using, update_fields,
  File "D:\Anaconda3\envs\lib\site-packages\django\db\models\base.py", line 887, in _save_table
    results = self._do_insert(cls._base_manager, using, fields, returning_fields, raw)
  File "D:\Anaconda3\envs\lib\site-packages\django\db\models\base.py", line 926, in _do_insert
    using=using, raw=raw,
  File "D:\Anaconda3\envs\lib\site-packages\django\db\models\manager.py", line 82, in manager_method
    return getattr(self.get_queryset(), name)(*args, **kwargs)
  File "D:\Anaconda3\envs\lib\site-packages\django\db\models\query.py", line 1204, in _insert
    return query.get_compiler(using=using).execute_sql(returning_fields)
  File "D:\Anaconda3\envs\lib\site-packages\django\db\models\sql\compiler.py", line 1391, in execute_sql
    cursor.execute(sql, params)
  File "D:\Anaconda3\envs\lib\site-packages\django\db\backends\utils.py", line 100, in execute
    return super().execute(sql, params)
  File "D:\Anaconda3\envs\lib\site-packages\django\db\backends\utils.py", line 68, in execute
    return self._execute_with_wrappers(sql, params, many=False, executor=self._execute)
  File "D:\Anaconda3\envs\lib\site-packages\django\db\backends\utils.py", line 77, in _execute_with_wrappers
    return executor(sql, params, many, context)
  File "D:\Anaconda3\envs\lib\site-packages\django\db\backends\utils.py", line 86, in _execute
    return self.cursor.execute(sql, params)
  File "D:\Anaconda3\envs\lib\site-packages\django\db\utils.py", line 90, in __exit__
    raise dj_exc_value.with_traceback(traceback) from exc_value
  File "D:\Anaconda3\envs\lib\site-packages\django\db\backends\utils.py", line 86, in _execute
    return self.cursor.execute(sql, params)
  File "D:\Anaconda3\envs\lib\site-packages\django\db\backends\mysql\base.py", line 75, in execute
    return self.cursor.execute(query, args)
  File "D:\Anaconda3\envs\lib\site-packages\pymysql\cursors.py", line 170, in execute
    result = self._query(query)
  File "D:\Anaconda3\envs\lib\site-packages\pymysql\cursors.py", line 328, in _query
    conn.query(q)
  File "D:\Anaconda3\envs\lib\site-packages\pymysql\connections.py", line 517, in query
    self._affected_rows = self._read_query_result(unbuffered=unbuffered)
  File "D:\Anaconda3\envs\lib\site-packages\pymysql\connections.py", line 732, in _read_query_result
    result.read()
  File "D:\Anaconda3\envs\lib\site-packages\pymysql\connections.py", line 1075, in read
    first_packet = self.connection._read_packet()
  File "D:\Anaconda3\envs\lib\site-packages\pymysql\connections.py", line 684, in _read_packet
    packet.check_error()
  File "D:\Anaconda3\envs\lib\site-packages\pymysql\protocol.py", line 220, in check_error
    err.raise_mysql_exception(self._data)
  File "D:\Anaconda3\envs\lib\site-packages\pymysql\err.py", line 109, in raise_mysql_exception
    raise errorclass(errno, errval)
django.db.utils.IntegrityError: (1048, "Column 'RealAmount' cannot be null")

更新物料库存数量出错
({'srid': '1824', 'presamount': Decimal('93'), 'checkamount': Decimal('93'), 'presunit': 'ml', 'pracamount': Decimal('108'), 'pracunit': 'ml', 'drawamount': Decimal('110'), 'drawunit': 'ml', 'loss': '0.00', 'precision': 0, 'stuffid': '04030002', 'stuffname': '酒石酸泰万菌素', 'stufftype': 0, 'stuffkind': '酒石酸泰万菌素', 'spec': '10kg/桶', 'package': '10kg/桶', 'producer': '内蒙中牧生物药业有限公司', 'batchno': '01', 'lrid': 0, 'content': Decimal('88.00'), 'cunit': '', 'water': Decimal('2.00'), 'impurity': Decimal('0.00'), 'rdensity': Decimal('1.0000'), 'mbatchno': '01', 'sdpid': 6808, 'ppid': 36}, {'srid': '1759', 'presamount': Decimal('30.0000'), 'checkamount': Decimal('30.0000'), 'presunit': 'g', 'pracamount': Decimal('15.0000'), 'pracunit': 'g', 'drawamount': Decimal('15.3000'), 'drawunit': 'g', 'loss': '0.00', 'precision': 4, 'stuffid': '0408034', 'stuffname': '无水葡萄糖', 'stufftype': 1, 'stuffkind': '无水葡萄糖', 'spec': '25kg/包', 'package': '25kg/包', 'producer': '西王药业有限公司', 'batchno': '20190901', 'lrid': 2939, 'content': Decimal('100.00'), 'cunit': '', 'water': Decimal('0.10'), 'impurity': Decimal('5.00'), 'rdensity': Decimal('1.3000'), 'mbatchno': '20190630XA', 'sdpid': 6808, 'ppid': 36})
--------------------
2020-08-19 17:34:04
FieldDoesNotExist("Stuffdrawpaper has no field named 'drawamount'")
Traceback (most recent call last):
  File "D:\Anaconda3\envs\lib\site-packages\django\db\models\options.py", line 581, in get_field
    return self.fields_map[field_name]
KeyError: 'drawamount'

During handling of the above exception, another exception occurred:

Traceback (most recent call last):
  File "d:\pyproject\GMPsystem\warehouse\models\warehousemodel.py", line 87, in update_stuffrepository_amount
    Stuffdrawpaper.objects.filter(autoid=sdpid).update(**kwargs)
  File "D:\Anaconda3\envs\lib\site-packages\django\db\models\query.py", line 748, in update
    query.add_update_values(kwargs)
  File "D:\Anaconda3\envs\lib\site-packages\django\db\models\sql\subqueries.py", line 117, in add_update_values
    field = self.get_meta().get_field(name)
  File "D:\Anaconda3\envs\lib\site-packages\django\db\models\options.py", line 583, in get_field
    raise FieldDoesNotExist("%s has no field named '%s'" % (self.object_name, field_name))
django.core.exceptions.FieldDoesNotExist: Stuffdrawpaper has no field named 'drawamount'

更新物料库存数量出错
({'srid': '1837', 'presamount': Decimal('93'), 'checkamount': Decimal('93'), 'presunit': 'ml', 'pracamount': Decimal('3'), 'pracunit': 'ml', 'drawamount': Decimal('3'), 'drawunit': 'ml', 'loss': '0.00', 'precision': 0, 'stuffid': '04030002', 'stuffname': '酒石酸泰万菌素', 'stufftype': 0, 'stuffkind': '酒石酸泰万菌素', 'spec': '10kg/桶', 'package': '10kg/桶', 'producer': '内蒙中牧生物药业有限公司', 'batchno': '02', 'lrid': 0, 'content': Decimal('88.00'), 'cunit': '', 'water': Decimal('2.00'), 'impurity': Decimal('0.00'), 'rdensity': Decimal('1.0000'), 'mbatchno': '01', 'sdpid': '6808', 'ppid': '36'}, {'srid': '1759', 'presamount': Decimal('30.0000'), 'checkamount': Decimal('30.0000'), 'presunit': 'g', 'pracamount': Decimal('15.0000'), 'pracunit': 'g', 'drawamount': Decimal('15.3000'), 'drawunit': 'g', 'loss': '0.00', 'precision': 4, 'stuffid': '0408034', 'stuffname': '无水葡萄糖', 'stufftype': 1, 'stuffkind': '无水葡萄糖', 'spec': '25kg/包', 'package': '25kg/包', 'producer': '西王药业有限公司', 'batchno': '20190901', 'lrid': 2939, 'content': Decimal('100.00'), 'cunit': '', 'water': Decimal('0.10'), 'impurity': Decimal('5.00'), 'rdensity': Decimal('1.3000'), 'mbatchno': '20190630XA', 'sdpid': '6808', 'ppid': '36'})
--------------------
2020-08-19 17:34:08
FieldDoesNotExist("Stuffdrawpaper has no field named 'drawamount'")
Traceback (most recent call last):
  File "D:\Anaconda3\envs\lib\site-packages\django\db\models\options.py", line 581, in get_field
    return self.fields_map[field_name]
KeyError: 'drawamount'

During handling of the above exception, another exception occurred:

Traceback (most recent call last):
  File "d:\pyproject\GMPsystem\warehouse\models\warehousemodel.py", line 87, in update_stuffrepository_amount
    Stuffdrawpaper.objects.filter(autoid=sdpid).update(**kwargs)
  File "D:\Anaconda3\envs\lib\site-packages\django\db\models\query.py", line 748, in update
    query.add_update_values(kwargs)
  File "D:\Anaconda3\envs\lib\site-packages\django\db\models\sql\subqueries.py", line 117, in add_update_values
    field = self.get_meta().get_field(name)
  File "D:\Anaconda3\envs\lib\site-packages\django\db\models\options.py", line 583, in get_field
    raise FieldDoesNotExist("%s has no field named '%s'" % (self.object_name, field_name))
django.core.exceptions.FieldDoesNotExist: Stuffdrawpaper has no field named 'drawamount'

更新物料库存数量出错
({'srid': '1837', 'presamount': Decimal('93'), 'checkamount': Decimal('93'), 'presunit': 'ml', 'pracamount': Decimal('3'), 'pracunit': 'ml', 'drawamount': Decimal('3'), 'drawunit': 'ml', 'loss': '0.00', 'precision': 0, 'stuffid': '04030002', 'stuffname': '酒石酸泰万菌素', 'stufftype': 0, 'stuffkind': '酒石酸泰万菌素', 'spec': '10kg/桶', 'package': '10kg/桶', 'producer': '内蒙中牧生物药业有限公司', 'batchno': '02', 'lrid': 0, 'content': Decimal('88.00'), 'cunit': '', 'water': Decimal('2.00'), 'impurity': Decimal('0.00'), 'rdensity': Decimal('1.0000'), 'mbatchno': '01', 'sdpid': '6808', 'ppid': '36'}, {'srid': '1759', 'presamount': Decimal('30.0000'), 'checkamount': Decimal('30.0000'), 'presunit': 'g', 'pracamount': Decimal('15.0000'), 'pracunit': 'g', 'drawamount': Decimal('15.3000'), 'drawunit': 'g', 'loss': '0.00', 'precision': 4, 'stuffid': '0408034', 'stuffname': '无水葡萄糖', 'stufftype': 1, 'stuffkind': '无水葡萄糖', 'spec': '25kg/包', 'package': '25kg/包', 'producer': '西王药业有限公司', 'batchno': '20190901', 'lrid': 2939, 'content': Decimal('100.00'), 'cunit': '', 'water': Decimal('0.10'), 'impurity': Decimal('5.00'), 'rdensity': Decimal('1.3000'), 'mbatchno': '20190630XA', 'sdpid': '6808', 'ppid': '36'})
--------------------
2020-08-19 17:35:39
FieldDoesNotExist("Stuffdrawpaper has no field named 'drawamount'")
Traceback (most recent call last):
  File "D:\Anaconda3\envs\lib\site-packages\django\db\models\options.py", line 581, in get_field
    return self.fields_map[field_name]
KeyError: 'drawamount'

During handling of the above exception, another exception occurred:

Traceback (most recent call last):
  File "d:\pyproject\GMPsystem\warehouse\models\warehousemodel.py", line 87, in update_stuffrepository_amount
    Stuffdrawpaper.objects.filter(autoid=sdpid).update(**kwargs)
  File "D:\Anaconda3\envs\lib\site-packages\django\db\models\query.py", line 748, in update
    query.add_update_values(kwargs)
  File "D:\Anaconda3\envs\lib\site-packages\django\db\models\sql\subqueries.py", line 117, in add_update_values
    field = self.get_meta().get_field(name)
  File "D:\Anaconda3\envs\lib\site-packages\django\db\models\options.py", line 583, in get_field
    raise FieldDoesNotExist("%s has no field named '%s'" % (self.object_name, field_name))
django.core.exceptions.FieldDoesNotExist: Stuffdrawpaper has no field named 'drawamount'

更新物料库存数量出错
({'srid': '1837', 'presamount': Decimal('93'), 'checkamount': Decimal('93'), 'presunit': 'ml', 'pracamount': Decimal('3'), 'pracunit': 'ml', 'drawamount': Decimal('3'), 'drawunit': 'ml', 'loss': '0.00', 'precision': 0, 'stuffid': '04030002', 'stuffname': '酒石酸泰万菌素', 'stufftype': 0, 'stuffkind': '酒石酸泰万菌素', 'spec': '10kg/桶', 'package': '10kg/桶', 'producer': '内蒙中牧生物药业有限公司', 'batchno': '02', 'lrid': 0, 'content': Decimal('88.00'), 'cunit': '', 'water': Decimal('2.00'), 'impurity': Decimal('0.00'), 'rdensity': Decimal('1.0000'), 'mbatchno': '01', 'sdpid': '6808', 'ppid': '36'}, {'srid': '1759', 'presamount': Decimal('30.0000'), 'checkamount': Decimal('30.0000'), 'presunit': 'g', 'pracamount': Decimal('15.0000'), 'pracunit': 'g', 'drawamount': Decimal('15.3000'), 'drawunit': 'g', 'loss': '0.00', 'precision': 4, 'stuffid': '0408034', 'stuffname': '无水葡萄糖', 'stufftype': 1, 'stuffkind': '无水葡萄糖', 'spec': '25kg/包', 'package': '25kg/包', 'producer': '西王药业有限公司', 'batchno': '20190901', 'lrid': 2939, 'content': Decimal('100.00'), 'cunit': '', 'water': Decimal('0.10'), 'impurity': Decimal('5.00'), 'rdensity': Decimal('1.3000'), 'mbatchno': '20190630XA', 'sdpid': '6808', 'ppid': '36'})
--------------------
2020-08-19 17:36:33
AttributeError("'str' object has no attribute 'utcoffset'")
Traceback (most recent call last):
  File "d:\pyproject\GMPsystem\warehouse\models\warehousemodel.py", line 87, in update_stuffrepository_amount
    Stuffdrawpaper.objects.filter(autoid=sdpid).update(**kwargs)
  File "D:\Anaconda3\envs\lib\site-packages\django\db\models\query.py", line 752, in update
    rows = query.get_compiler(self.db).execute_sql(CURSOR)
  File "D:\Anaconda3\envs\lib\site-packages\django\db\models\sql\compiler.py", line 1499, in execute_sql
    cursor = super().execute_sql(result_type)
  File "D:\Anaconda3\envs\lib\site-packages\django\db\models\sql\compiler.py", line 1138, in execute_sql
    sql, params = self.as_sql()
  File "D:\Anaconda3\envs\lib\site-packages\django\db\models\sql\compiler.py", line 1465, in as_sql
    val = field.get_db_prep_save(val, connection=self.connection)
  File "D:\Anaconda3\envs\lib\site-packages\django\db\models\fields\__init__.py", line 821, in get_db_prep_save
    return self.get_db_prep_value(value, connection=connection, prepared=False)
  File "D:\Anaconda3\envs\lib\site-packages\django\db\models\fields\__init__.py", line 1376, in get_db_prep_value
    return connection.ops.adapt_datetimefield_value(value)
  File "D:\Anaconda3\envs\lib\site-packages\django\db\backends\mysql\operations.py", line 205, in adapt_datetimefield_value
    if timezone.is_aware(value):
  File "D:\Anaconda3\envs\lib\site-packages\django\utils\timezone.py", line 248, in is_aware
    return value.utcoffset() is not None
AttributeError: 'str' object has no attribute 'utcoffset'

更新物料库存数量出错
({'srid': '1837', 'presamount': Decimal('93'), 'checkamount': Decimal('93'), 'presunit': 'ml', 'pracamount': Decimal('3'), 'pracunit': 'ml', 'drawamount': Decimal('3'), 'drawunit': 'ml', 'loss': '0.00', 'precision': 0, 'stuffid': '04030002', 'stuffname': '酒石酸泰万菌素', 'stufftype': 0, 'stuffkind': '酒石酸泰万菌素', 'spec': '10kg/桶', 'package': '10kg/桶', 'producer': '内蒙中牧生物药业有限公司', 'batchno': '02', 'lrid': 0, 'content': Decimal('88.00'), 'cunit': '', 'water': Decimal('2.00'), 'impurity': Decimal('0.00'), 'rdensity': Decimal('1.0000'), 'mbatchno': '01', 'sdpid': '6808', 'ppid': '36'}, {'srid': '1759', 'presamount': Decimal('30.0000'), 'checkamount': Decimal('30.0000'), 'presunit': 'g', 'pracamount': Decimal('15.0000'), 'pracunit': 'g', 'drawamount': Decimal('15.3000'), 'drawunit': 'g', 'loss': '0.00', 'precision': 4, 'stuffid': '0408034', 'stuffname': '无水葡萄糖', 'stufftype': 1, 'stuffkind': '无水葡萄糖', 'spec': '25kg/包', 'package': '25kg/包', 'producer': '西王药业有限公司', 'batchno': '20190901', 'lrid': 2939, 'content': Decimal('100.00'), 'cunit': '', 'water': Decimal('0.10'), 'impurity': Decimal('5.00'), 'rdensity': Decimal('1.3000'), 'mbatchno': '20190630XA', 'sdpid': '6808', 'ppid': '36'})
--------------------
2020-08-19 17:37:54
KeyError('autoid')
Traceback (most recent call last):
  File "d:\pyproject\GMPsystem\warehouse\models\warehousemodel.py", line 85, in update_stuffrepository_amount
    sdpid = kwargs['autoid']
KeyError: 'autoid'

更新物料库存数量出错
({'srid': '1837', 'presamount': Decimal('93'), 'checkamount': Decimal('93'), 'presunit': 'ml', 'pracamount': Decimal('3'), 'pracunit': 'ml', 'drawamount': Decimal('3'), 'drawunit': 'ml', 'loss': '0.00', 'precision': 0, 'stuffid': '04030002', 'stuffname': '酒石酸泰万菌素', 'stufftype': 0, 'stuffkind': '酒石酸泰万菌素', 'spec': '10kg/桶', 'package': '10kg/桶', 'producer': '内蒙中牧生物药业有限公司', 'batchno': '02', 'lrid': 0, 'content': Decimal('88.00'), 'cunit': '', 'water': Decimal('2.00'), 'impurity': Decimal('0.00'), 'rdensity': Decimal('1.0000'), 'mbatchno': '01', 'sdpid': '6808', 'ppid': '36'}, {'srid': '1759', 'presamount': Decimal('30.0000'), 'checkamount': Decimal('30.0000'), 'presunit': 'g', 'pracamount': Decimal('15.0000'), 'pracunit': 'g', 'drawamount': Decimal('15.3000'), 'drawunit': 'g', 'loss': '0.00', 'precision': 4, 'stuffid': '0408034', 'stuffname': '无水葡萄糖', 'stufftype': 1, 'stuffkind': '无水葡萄糖', 'spec': '25kg/包', 'package': '25kg/包', 'producer': '西王药业有限公司', 'batchno': '20190901', 'lrid': 2939, 'content': Decimal('100.00'), 'cunit': '', 'water': Decimal('0.10'), 'impurity': Decimal('5.00'), 'rdensity': Decimal('1.3000'), 'mbatchno': '20190630XA', 'sdpid': '6808', 'ppid': '36'})
--------------------