
2020-10-14 10:04:44
TypeError("Field 'autoid' expected a number but got <warehouse.modules.purstuffcheckinmodule.PurStuffCheckInModule object at 0x0000022DC3AE2B80>.")
Traceback (most recent call last):
  File "D:\Anaconda3\envs\py3.8.5\lib\site-packages\django\db\models\fields\__init__.py", line 1774, in get_prep_value
    return int(value)
TypeError: int() argument must be a string, a bytes-like object or a number, not 'PurStuffCheckInModule'

The above exception was the direct cause of the following exception:

Traceback (most recent call last):
  File "D:\pyproject\gmpsystem\labrecord\models\labmodel.py", line 31, in get_labitem
    res = Labrecordsdetail.objects.filter(**kwargs)
  File "D:\Anaconda3\envs\py3.8.5\lib\site-packages\django\db\models\manager.py", line 85, in manager_method
    return getattr(self.get_queryset(), name)(*args, **kwargs)
  File "D:\Anaconda3\envs\py3.8.5\lib\site-packages\django\db\models\query.py", line 942, in filter
    return self._filter_or_exclude(False, *args, **kwargs)
  File "D:\Anaconda3\envs\py3.8.5\lib\site-packages\django\db\models\query.py", line 962, in _filter_or_exclude
    clone._filter_or_exclude_inplace(negate, *args, **kwargs)
  File "D:\Anaconda3\envs\py3.8.5\lib\site-packages\django\db\models\query.py", line 969, in _filter_or_exclude_inplace
    self._query.add_q(Q(*args, **kwargs))
  File "D:\Anaconda3\envs\py3.8.5\lib\site-packages\django\db\models\sql\query.py", line 1358, in add_q
    clause, _ = self._add_q(q_object, self.used_aliases)
  File "D:\Anaconda3\envs\py3.8.5\lib\site-packages\django\db\models\sql\query.py", line 1377, in _add_q
    child_clause, needed_inner = self.build_filter(
  File "D:\Anaconda3\envs\py3.8.5\lib\site-packages\django\db\models\sql\query.py", line 1319, in build_filter
    condition = self.build_lookup(lookups, col, value)
  File "D:\Anaconda3\envs\py3.8.5\lib\site-packages\django\db\models\sql\query.py", line 1165, in build_lookup
    lookup = lookup_class(lhs, rhs)
  File "D:\Anaconda3\envs\py3.8.5\lib\site-packages\django\db\models\lookups.py", line 24, in __init__
    self.rhs = self.get_prep_lookup()
  File "D:\Anaconda3\envs\py3.8.5\lib\site-packages\django\db\models\lookups.py", line 74, in get_prep_lookup
    return self.lhs.output_field.get_prep_value(self.rhs)
  File "D:\Anaconda3\envs\py3.8.5\lib\site-packages\django\db\models\fields\__init__.py", line 1776, in get_prep_value
    raise e.__class__(
TypeError: Field 'autoid' expected a number but got <warehouse.modules.purstuffcheckinmodule.PurStuffCheckInModule object at 0x0000022DC3AE2B80>.

获取检验项目时出错
labvalue
args=["putintype"]
kwargs={"autoid": null}
--------------------
2020-10-14 10:34:20
OperationalError(1054, "Unknown column 'CheckInDatse' in 'field list'")
Traceback (most recent call last):
  File "D:\Anaconda3\envs\py3.8.5\lib\site-packages\django\db\backends\utils.py", line 84, in _execute
    return self.cursor.execute(sql, params)
  File "D:\Anaconda3\envs\py3.8.5\lib\site-packages\django\db\backends\mysql\base.py", line 74, in execute
    return self.cursor.execute(query, args)
  File "D:\Anaconda3\envs\py3.8.5\lib\site-packages\pymysql\cursors.py", line 163, in execute
    result = self._query(query)
  File "D:\Anaconda3\envs\py3.8.5\lib\site-packages\pymysql\cursors.py", line 321, in _query
    conn.query(q)
  File "D:\Anaconda3\envs\py3.8.5\lib\site-packages\pymysql\connections.py", line 505, in query
    self._affected_rows = self._read_query_result(unbuffered=unbuffered)
  File "D:\Anaconda3\envs\py3.8.5\lib\site-packages\pymysql\connections.py", line 724, in _read_query_result
    result.read()
  File "D:\Anaconda3\envs\py3.8.5\lib\site-packages\pymysql\connections.py", line 1069, in read
    first_packet = self.connection._read_packet()
  File "D:\Anaconda3\envs\py3.8.5\lib\site-packages\pymysql\connections.py", line 676, in _read_packet
    packet.raise_for_error()
  File "D:\Anaconda3\envs\py3.8.5\lib\site-packages\pymysql\protocol.py", line 223, in raise_for_error
    err.raise_mysql_exception(self._data)
  File "D:\Anaconda3\envs\py3.8.5\lib\site-packages\pymysql\err.py", line 107, in raise_mysql_exception
    raise errorclass(errno, errval)
pymysql.err.OperationalError: (1054, "Unknown column 'CheckInDatse' in 'field list'")

The above exception was the direct cause of the following exception:

Traceback (most recent call last):
  File "D:\pyproject\gmpsystem\warehouse\models\warehousemodel.py", line 77, in update_stuffrepository
    return Stuffrepository.objects.create(**kwargs)
  File "D:\Anaconda3\envs\py3.8.5\lib\site-packages\django\db\models\manager.py", line 85, in manager_method
    return getattr(self.get_queryset(), name)(*args, **kwargs)
  File "D:\Anaconda3\envs\py3.8.5\lib\site-packages\django\db\models\query.py", line 447, in create
    obj.save(force_insert=True, using=self.db)
  File "D:\Anaconda3\envs\py3.8.5\lib\site-packages\django\db\models\base.py", line 750, in save
    self.save_base(using=using, force_insert=force_insert,
  File "D:\Anaconda3\envs\py3.8.5\lib\site-packages\django\db\models\base.py", line 787, in save_base
    updated = self._save_table(
  File "D:\Anaconda3\envs\py3.8.5\lib\site-packages\django\db\models\base.py", line 892, in _save_table
    results = self._do_insert(cls._base_manager, using, fields, returning_fields, raw)
  File "D:\Anaconda3\envs\py3.8.5\lib\site-packages\django\db\models\base.py", line 930, in _do_insert
    return manager._insert(
  File "D:\Anaconda3\envs\py3.8.5\lib\site-packages\django\db\models\manager.py", line 85, in manager_method
    return getattr(self.get_queryset(), name)(*args, **kwargs)
  File "D:\Anaconda3\envs\py3.8.5\lib\site-packages\django\db\models\query.py", line 1249, in _insert
    return query.get_compiler(using=using).execute_sql(returning_fields)
  File "D:\Anaconda3\envs\py3.8.5\lib\site-packages\django\db\models\sql\compiler.py", line 1395, in execute_sql
    cursor.execute(sql, params)
  File "D:\Anaconda3\envs\py3.8.5\lib\site-packages\django\db\backends\utils.py", line 98, in execute
    return super().execute(sql, params)
  File "D:\Anaconda3\envs\py3.8.5\lib\site-packages\django\db\backends\utils.py", line 66, in execute
    return self._execute_with_wrappers(sql, params, many=False, executor=self._execute)
  File "D:\Anaconda3\envs\py3.8.5\lib\site-packages\django\db\backends\utils.py", line 75, in _execute_with_wrappers
    return executor(sql, params, many, context)
  File "D:\Anaconda3\envs\py3.8.5\lib\site-packages\django\db\backends\utils.py", line 84, in _execute
    return self.cursor.execute(sql, params)
  File "D:\Anaconda3\envs\py3.8.5\lib\site-packages\django\db\utils.py", line 90, in __exit__
    raise dj_exc_value.with_traceback(traceback) from exc_value
  File "D:\Anaconda3\envs\py3.8.5\lib\site-packages\django\db\backends\utils.py", line 84, in _execute
    return self.cursor.execute(sql, params)
  File "D:\Anaconda3\envs\py3.8.5\lib\site-packages\django\db\backends\mysql\base.py", line 74, in execute
    return self.cursor.execute(query, args)
  File "D:\Anaconda3\envs\py3.8.5\lib\site-packages\pymysql\cursors.py", line 163, in execute
    result = self._query(query)
  File "D:\Anaconda3\envs\py3.8.5\lib\site-packages\pymysql\cursors.py", line 321, in _query
    conn.query(q)
  File "D:\Anaconda3\envs\py3.8.5\lib\site-packages\pymysql\connections.py", line 505, in query
    self._affected_rows = self._read_query_result(unbuffered=unbuffered)
  File "D:\Anaconda3\envs\py3.8.5\lib\site-packages\pymysql\connections.py", line 724, in _read_query_result
    result.read()
  File "D:\Anaconda3\envs\py3.8.5\lib\site-packages\pymysql\connections.py", line 1069, in read
    first_packet = self.connection._read_packet()
  File "D:\Anaconda3\envs\py3.8.5\lib\site-packages\pymysql\connections.py", line 676, in _read_packet
    packet.raise_for_error()
  File "D:\Anaconda3\envs\py3.8.5\lib\site-packages\pymysql\protocol.py", line 223, in raise_for_error
    err.raise_mysql_exception(self._data)
  File "D:\Anaconda3\envs\py3.8.5\lib\site-packages\pymysql\err.py", line 107, in raise_mysql_exception
    raise errorclass(errno, errval)
django.db.utils.OperationalError: (1054, "Unknown column 'CheckInDatse' in 'field list'")

更新物料库存时出错
kwargs={"content": null, "cunit": "%", "water": null, "rdensity": null, "impurity": null, "position": "", "stuffkind": "十孔泡沫盒0599054", "stufftype": 3, "allowno": "", "nextcheckdate": null, "spamount": 1, "ciid": 741, "pltype": 0, "stuffid": "0599054", "stuffname": "十孔泡沫盒", "spec": "盖外尺寸：330mm×150mm×18mm(±1mm)，孔深", "package": "60套/件", "supid": "", "producer": "新兴县厚德五金塑料制品有限公司", "makedate": null, "batchno": "20190601", "mbatchno": "", "expireddate": null, "amount": null, "piamount": null, "basicunit": "套", "checkindate": null, "putindate": null, "lrid": 19, "warehousemanid": "001", "warehousemanname": "sys02"}
--------------------
2020-10-14 10:36:15
IntegrityError(1048, "Column 'mpAmount' cannot be null")
Traceback (most recent call last):
  File "D:\Anaconda3\envs\py3.8.5\lib\site-packages\django\db\backends\utils.py", line 84, in _execute
    return self.cursor.execute(sql, params)
  File "D:\Anaconda3\envs\py3.8.5\lib\site-packages\django\db\backends\mysql\base.py", line 74, in execute
    return self.cursor.execute(query, args)
  File "D:\Anaconda3\envs\py3.8.5\lib\site-packages\pymysql\cursors.py", line 163, in execute
    result = self._query(query)
  File "D:\Anaconda3\envs\py3.8.5\lib\site-packages\pymysql\cursors.py", line 321, in _query
    conn.query(q)
  File "D:\Anaconda3\envs\py3.8.5\lib\site-packages\pymysql\connections.py", line 505, in query
    self._affected_rows = self._read_query_result(unbuffered=unbuffered)
  File "D:\Anaconda3\envs\py3.8.5\lib\site-packages\pymysql\connections.py", line 724, in _read_query_result
    result.read()
  File "D:\Anaconda3\envs\py3.8.5\lib\site-packages\pymysql\connections.py", line 1069, in read
    first_packet = self.connection._read_packet()
  File "D:\Anaconda3\envs\py3.8.5\lib\site-packages\pymysql\connections.py", line 676, in _read_packet
    packet.raise_for_error()
  File "D:\Anaconda3\envs\py3.8.5\lib\site-packages\pymysql\protocol.py", line 223, in raise_for_error
    err.raise_mysql_exception(self._data)
  File "D:\Anaconda3\envs\py3.8.5\lib\site-packages\pymysql\err.py", line 107, in raise_mysql_exception
    raise errorclass(errno, errval)
pymysql.err.IntegrityError: (1048, "Column 'mpAmount' cannot be null")

The above exception was the direct cause of the following exception:

Traceback (most recent call last):
  File "D:\pyproject\gmpsystem\warehouse\models\warehousemodel.py", line 77, in update_stuffrepository
    return Stuffrepository.objects.create(**kwargs)
  File "D:\Anaconda3\envs\py3.8.5\lib\site-packages\django\db\models\manager.py", line 85, in manager_method
    return getattr(self.get_queryset(), name)(*args, **kwargs)
  File "D:\Anaconda3\envs\py3.8.5\lib\site-packages\django\db\models\query.py", line 447, in create
    obj.save(force_insert=True, using=self.db)
  File "D:\Anaconda3\envs\py3.8.5\lib\site-packages\django\db\models\base.py", line 750, in save
    self.save_base(using=using, force_insert=force_insert,
  File "D:\Anaconda3\envs\py3.8.5\lib\site-packages\django\db\models\base.py", line 787, in save_base
    updated = self._save_table(
  File "D:\Anaconda3\envs\py3.8.5\lib\site-packages\django\db\models\base.py", line 892, in _save_table
    results = self._do_insert(cls._base_manager, using, fields, returning_fields, raw)
  File "D:\Anaconda3\envs\py3.8.5\lib\site-packages\django\db\models\base.py", line 930, in _do_insert
    return manager._insert(
  File "D:\Anaconda3\envs\py3.8.5\lib\site-packages\django\db\models\manager.py", line 85, in manager_method
    return getattr(self.get_queryset(), name)(*args, **kwargs)
  File "D:\Anaconda3\envs\py3.8.5\lib\site-packages\django\db\models\query.py", line 1249, in _insert
    return query.get_compiler(using=using).execute_sql(returning_fields)
  File "D:\Anaconda3\envs\py3.8.5\lib\site-packages\django\db\models\sql\compiler.py", line 1395, in execute_sql
    cursor.execute(sql, params)
  File "D:\Anaconda3\envs\py3.8.5\lib\site-packages\django\db\backends\utils.py", line 98, in execute
    return super().execute(sql, params)
  File "D:\Anaconda3\envs\py3.8.5\lib\site-packages\django\db\backends\utils.py", line 66, in execute
    return self._execute_with_wrappers(sql, params, many=False, executor=self._execute)
  File "D:\Anaconda3\envs\py3.8.5\lib\site-packages\django\db\backends\utils.py", line 75, in _execute_with_wrappers
    return executor(sql, params, many, context)
  File "D:\Anaconda3\envs\py3.8.5\lib\site-packages\django\db\backends\utils.py", line 84, in _execute
    return self.cursor.execute(sql, params)
  File "D:\Anaconda3\envs\py3.8.5\lib\site-packages\django\db\utils.py", line 90, in __exit__
    raise dj_exc_value.with_traceback(traceback) from exc_value
  File "D:\Anaconda3\envs\py3.8.5\lib\site-packages\django\db\backends\utils.py", line 84, in _execute
    return self.cursor.execute(sql, params)
  File "D:\Anaconda3\envs\py3.8.5\lib\site-packages\django\db\backends\mysql\base.py", line 74, in execute
    return self.cursor.execute(query, args)
  File "D:\Anaconda3\envs\py3.8.5\lib\site-packages\pymysql\cursors.py", line 163, in execute
    result = self._query(query)
  File "D:\Anaconda3\envs\py3.8.5\lib\site-packages\pymysql\cursors.py", line 321, in _query
    conn.query(q)
  File "D:\Anaconda3\envs\py3.8.5\lib\site-packages\pymysql\connections.py", line 505, in query
    self._affected_rows = self._read_query_result(unbuffered=unbuffered)
  File "D:\Anaconda3\envs\py3.8.5\lib\site-packages\pymysql\connections.py", line 724, in _read_query_result
    result.read()
  File "D:\Anaconda3\envs\py3.8.5\lib\site-packages\pymysql\connections.py", line 1069, in read
    first_packet = self.connection._read_packet()
  File "D:\Anaconda3\envs\py3.8.5\lib\site-packages\pymysql\connections.py", line 676, in _read_packet
    packet.raise_for_error()
  File "D:\Anaconda3\envs\py3.8.5\lib\site-packages\pymysql\protocol.py", line 223, in raise_for_error
    err.raise_mysql_exception(self._data)
  File "D:\Anaconda3\envs\py3.8.5\lib\site-packages\pymysql\err.py", line 107, in raise_mysql_exception
    raise errorclass(errno, errval)
django.db.utils.IntegrityError: (1048, "Column 'mpAmount' cannot be null")

更新物料库存时出错
kwargs={"content": null, "cunit": "%", "water": null, "rdensity": null, "impurity": null, "position": "", "stuffkind": "十孔泡沫盒0599054", "stufftype": 3, "allowno": "", "nextcheckdate": null, "spamount": 1, "ciid": 741, "pltype": 0, "stuffid": "0599054", "stuffname": "十孔泡沫盒", "spec": "盖外尺寸：330mm×150mm×18mm(±1mm)，孔深", "package": "60套/件", "supid": "", "producer": "新兴县厚德五金塑料制品有限公司", "makedate": null, "batchno": "20190601", "mbatchno": "", "expireddate": null, "amount": null, "piamount": null, "basicunit": "套", "checkindate": null, "putindate": null, "lrid": 19, "warehousemanid": "001", "warehousemanname": "sys02"}
--------------------
2020-10-14 10:39:15
IntegrityError(1048, "Column 'cEffect' cannot be null")
Traceback (most recent call last):
  File "D:\Anaconda3\envs\py3.8.5\lib\site-packages\django\db\backends\utils.py", line 84, in _execute
    return self.cursor.execute(sql, params)
  File "D:\Anaconda3\envs\py3.8.5\lib\site-packages\django\db\backends\mysql\base.py", line 74, in execute
    return self.cursor.execute(query, args)
  File "D:\Anaconda3\envs\py3.8.5\lib\site-packages\pymysql\cursors.py", line 163, in execute
    result = self._query(query)
  File "D:\Anaconda3\envs\py3.8.5\lib\site-packages\pymysql\cursors.py", line 321, in _query
    conn.query(q)
  File "D:\Anaconda3\envs\py3.8.5\lib\site-packages\pymysql\connections.py", line 505, in query
    self._affected_rows = self._read_query_result(unbuffered=unbuffered)
  File "D:\Anaconda3\envs\py3.8.5\lib\site-packages\pymysql\connections.py", line 724, in _read_query_result
    result.read()
  File "D:\Anaconda3\envs\py3.8.5\lib\site-packages\pymysql\connections.py", line 1069, in read
    first_packet = self.connection._read_packet()
  File "D:\Anaconda3\envs\py3.8.5\lib\site-packages\pymysql\connections.py", line 676, in _read_packet
    packet.raise_for_error()
  File "D:\Anaconda3\envs\py3.8.5\lib\site-packages\pymysql\protocol.py", line 223, in raise_for_error
    err.raise_mysql_exception(self._data)
  File "D:\Anaconda3\envs\py3.8.5\lib\site-packages\pymysql\err.py", line 107, in raise_mysql_exception
    raise errorclass(errno, errval)
pymysql.err.IntegrityError: (1048, "Column 'cEffect' cannot be null")

The above exception was the direct cause of the following exception:

Traceback (most recent call last):
  File "D:\pyproject\gmpsystem\warehouse\models\warehousemodel.py", line 77, in update_stuffrepository
    return Stuffrepository.objects.create(**kwargs)
  File "D:\Anaconda3\envs\py3.8.5\lib\site-packages\django\db\models\manager.py", line 85, in manager_method
    return getattr(self.get_queryset(), name)(*args, **kwargs)
  File "D:\Anaconda3\envs\py3.8.5\lib\site-packages\django\db\models\query.py", line 447, in create
    obj.save(force_insert=True, using=self.db)
  File "D:\Anaconda3\envs\py3.8.5\lib\site-packages\django\db\models\base.py", line 750, in save
    self.save_base(using=using, force_insert=force_insert,
  File "D:\Anaconda3\envs\py3.8.5\lib\site-packages\django\db\models\base.py", line 787, in save_base
    updated = self._save_table(
  File "D:\Anaconda3\envs\py3.8.5\lib\site-packages\django\db\models\base.py", line 892, in _save_table
    results = self._do_insert(cls._base_manager, using, fields, returning_fields, raw)
  File "D:\Anaconda3\envs\py3.8.5\lib\site-packages\django\db\models\base.py", line 930, in _do_insert
    return manager._insert(
  File "D:\Anaconda3\envs\py3.8.5\lib\site-packages\django\db\models\manager.py", line 85, in manager_method
    return getattr(self.get_queryset(), name)(*args, **kwargs)
  File "D:\Anaconda3\envs\py3.8.5\lib\site-packages\django\db\models\query.py", line 1249, in _insert
    return query.get_compiler(using=using).execute_sql(returning_fields)
  File "D:\Anaconda3\envs\py3.8.5\lib\site-packages\django\db\models\sql\compiler.py", line 1395, in execute_sql
    cursor.execute(sql, params)
  File "D:\Anaconda3\envs\py3.8.5\lib\site-packages\django\db\backends\utils.py", line 98, in execute
    return super().execute(sql, params)
  File "D:\Anaconda3\envs\py3.8.5\lib\site-packages\django\db\backends\utils.py", line 66, in execute
    return self._execute_with_wrappers(sql, params, many=False, executor=self._execute)
  File "D:\Anaconda3\envs\py3.8.5\lib\site-packages\django\db\backends\utils.py", line 75, in _execute_with_wrappers
    return executor(sql, params, many, context)
  File "D:\Anaconda3\envs\py3.8.5\lib\site-packages\django\db\backends\utils.py", line 84, in _execute
    return self.cursor.execute(sql, params)
  File "D:\Anaconda3\envs\py3.8.5\lib\site-packages\django\db\utils.py", line 90, in __exit__
    raise dj_exc_value.with_traceback(traceback) from exc_value
  File "D:\Anaconda3\envs\py3.8.5\lib\site-packages\django\db\backends\utils.py", line 84, in _execute
    return self.cursor.execute(sql, params)
  File "D:\Anaconda3\envs\py3.8.5\lib\site-packages\django\db\backends\mysql\base.py", line 74, in execute
    return self.cursor.execute(query, args)
  File "D:\Anaconda3\envs\py3.8.5\lib\site-packages\pymysql\cursors.py", line 163, in execute
    result = self._query(query)
  File "D:\Anaconda3\envs\py3.8.5\lib\site-packages\pymysql\cursors.py", line 321, in _query
    conn.query(q)
  File "D:\Anaconda3\envs\py3.8.5\lib\site-packages\pymysql\connections.py", line 505, in query
    self._affected_rows = self._read_query_result(unbuffered=unbuffered)
  File "D:\Anaconda3\envs\py3.8.5\lib\site-packages\pymysql\connections.py", line 724, in _read_query_result
    result.read()
  File "D:\Anaconda3\envs\py3.8.5\lib\site-packages\pymysql\connections.py", line 1069, in read
    first_packet = self.connection._read_packet()
  File "D:\Anaconda3\envs\py3.8.5\lib\site-packages\pymysql\connections.py", line 676, in _read_packet
    packet.raise_for_error()
  File "D:\Anaconda3\envs\py3.8.5\lib\site-packages\pymysql\protocol.py", line 223, in raise_for_error
    err.raise_mysql_exception(self._data)
  File "D:\Anaconda3\envs\py3.8.5\lib\site-packages\pymysql\err.py", line 107, in raise_mysql_exception
    raise errorclass(errno, errval)
django.db.utils.IntegrityError: (1048, "Column 'cEffect' cannot be null")

更新物料库存时出错
kwargs={"content": null, "cunit": "%", "water": null, "rdensity": null, "impurity": null, "position": "", "stuffkind": "十孔泡沫盒0599054", "stufftype": 3, "allowno": "", "nextcheckdate": null, "spamount": 1, "ciid": 741, "pltype": 0, "stuffid": "0599054", "stuffname": "十孔泡沫盒", "spec": "盖外尺寸：330mm×150mm×18mm(±1mm)，孔深", "package": "60套/件", "supid": "", "producer": "新兴县厚德五金塑料制品有限公司", "makedate": null, "batchno": "20190601", "mbatchno": "", "expireddate": null, "amount": null, "piamount": null, "basicunit": "套", "checkindate": null, "putindate": null, "lrid": 19, "warehousemanid": "001", "warehousemanname": "sys02"}
--------------------
2020-10-14 10:59:56
IntegrityError(1062, "Duplicate entry '0-741' for key 'dc'")
Traceback (most recent call last):
  File "D:\Anaconda3\envs\py3.8.5\lib\site-packages\django\db\backends\utils.py", line 84, in _execute
    return self.cursor.execute(sql, params)
  File "D:\Anaconda3\envs\py3.8.5\lib\site-packages\django\db\backends\mysql\base.py", line 74, in execute
    return self.cursor.execute(query, args)
  File "D:\Anaconda3\envs\py3.8.5\lib\site-packages\pymysql\cursors.py", line 163, in execute
    result = self._query(query)
  File "D:\Anaconda3\envs\py3.8.5\lib\site-packages\pymysql\cursors.py", line 321, in _query
    conn.query(q)
  File "D:\Anaconda3\envs\py3.8.5\lib\site-packages\pymysql\connections.py", line 505, in query
    self._affected_rows = self._read_query_result(unbuffered=unbuffered)
  File "D:\Anaconda3\envs\py3.8.5\lib\site-packages\pymysql\connections.py", line 724, in _read_query_result
    result.read()
  File "D:\Anaconda3\envs\py3.8.5\lib\site-packages\pymysql\connections.py", line 1069, in read
    first_packet = self.connection._read_packet()
  File "D:\Anaconda3\envs\py3.8.5\lib\site-packages\pymysql\connections.py", line 676, in _read_packet
    packet.raise_for_error()
  File "D:\Anaconda3\envs\py3.8.5\lib\site-packages\pymysql\protocol.py", line 223, in raise_for_error
    err.raise_mysql_exception(self._data)
  File "D:\Anaconda3\envs\py3.8.5\lib\site-packages\pymysql\err.py", line 107, in raise_mysql_exception
    raise errorclass(errno, errval)
pymysql.err.IntegrityError: (1062, "Duplicate entry '0-741' for key 'dc'")

The above exception was the direct cause of the following exception:

Traceback (most recent call last):
  File "D:\pyproject\gmpsystem\warehouse\models\warehousemodel.py", line 77, in update_stuffrepository
    return Stuffrepository.objects.create(**kwargs)
  File "D:\Anaconda3\envs\py3.8.5\lib\site-packages\django\db\models\manager.py", line 85, in manager_method
    return getattr(self.get_queryset(), name)(*args, **kwargs)
  File "D:\Anaconda3\envs\py3.8.5\lib\site-packages\django\db\models\query.py", line 447, in create
    obj.save(force_insert=True, using=self.db)
  File "D:\Anaconda3\envs\py3.8.5\lib\site-packages\django\db\models\base.py", line 750, in save
    self.save_base(using=using, force_insert=force_insert,
  File "D:\Anaconda3\envs\py3.8.5\lib\site-packages\django\db\models\base.py", line 787, in save_base
    updated = self._save_table(
  File "D:\Anaconda3\envs\py3.8.5\lib\site-packages\django\db\models\base.py", line 892, in _save_table
    results = self._do_insert(cls._base_manager, using, fields, returning_fields, raw)
  File "D:\Anaconda3\envs\py3.8.5\lib\site-packages\django\db\models\base.py", line 930, in _do_insert
    return manager._insert(
  File "D:\Anaconda3\envs\py3.8.5\lib\site-packages\django\db\models\manager.py", line 85, in manager_method
    return getattr(self.get_queryset(), name)(*args, **kwargs)
  File "D:\Anaconda3\envs\py3.8.5\lib\site-packages\django\db\models\query.py", line 1249, in _insert
    return query.get_compiler(using=using).execute_sql(returning_fields)
  File "D:\Anaconda3\envs\py3.8.5\lib\site-packages\django\db\models\sql\compiler.py", line 1395, in execute_sql
    cursor.execute(sql, params)
  File "D:\Anaconda3\envs\py3.8.5\lib\site-packages\django\db\backends\utils.py", line 98, in execute
    return super().execute(sql, params)
  File "D:\Anaconda3\envs\py3.8.5\lib\site-packages\django\db\backends\utils.py", line 66, in execute
    return self._execute_with_wrappers(sql, params, many=False, executor=self._execute)
  File "D:\Anaconda3\envs\py3.8.5\lib\site-packages\django\db\backends\utils.py", line 75, in _execute_with_wrappers
    return executor(sql, params, many, context)
  File "D:\Anaconda3\envs\py3.8.5\lib\site-packages\django\db\backends\utils.py", line 84, in _execute
    return self.cursor.execute(sql, params)
  File "D:\Anaconda3\envs\py3.8.5\lib\site-packages\django\db\utils.py", line 90, in __exit__
    raise dj_exc_value.with_traceback(traceback) from exc_value
  File "D:\Anaconda3\envs\py3.8.5\lib\site-packages\django\db\backends\utils.py", line 84, in _execute
    return self.cursor.execute(sql, params)
  File "D:\Anaconda3\envs\py3.8.5\lib\site-packages\django\db\backends\mysql\base.py", line 74, in execute
    return self.cursor.execute(query, args)
  File "D:\Anaconda3\envs\py3.8.5\lib\site-packages\pymysql\cursors.py", line 163, in execute
    result = self._query(query)
  File "D:\Anaconda3\envs\py3.8.5\lib\site-packages\pymysql\cursors.py", line 321, in _query
    conn.query(q)
  File "D:\Anaconda3\envs\py3.8.5\lib\site-packages\pymysql\connections.py", line 505, in query
    self._affected_rows = self._read_query_result(unbuffered=unbuffered)
  File "D:\Anaconda3\envs\py3.8.5\lib\site-packages\pymysql\connections.py", line 724, in _read_query_result
    result.read()
  File "D:\Anaconda3\envs\py3.8.5\lib\site-packages\pymysql\connections.py", line 1069, in read
    first_packet = self.connection._read_packet()
  File "D:\Anaconda3\envs\py3.8.5\lib\site-packages\pymysql\connections.py", line 676, in _read_packet
    packet.raise_for_error()
  File "D:\Anaconda3\envs\py3.8.5\lib\site-packages\pymysql\protocol.py", line 223, in raise_for_error
    err.raise_mysql_exception(self._data)
  File "D:\Anaconda3\envs\py3.8.5\lib\site-packages\pymysql\err.py", line 107, in raise_mysql_exception
    raise errorclass(errno, errval)
django.db.utils.IntegrityError: (1062, "Duplicate entry '0-741' for key 'dc'")

更新物料库存时出错
kwargs={"content": null, "cunit": "%", "water": null, "rdensity": null, "impurity": null, "position": "", "stuffkind": "十孔泡沫盒0599054", "stufftype": 3, "allowno": "", "nextcheckdate": null, "spamount": 1, "spunit": "套", "basicamount": null, "ciid": 741, "pltype": 0, "stuffid": "0599054", "stuffname": "十孔泡沫盒", "spec": "盖外尺寸：330mm×150mm×18mm(±1mm)，孔深", "package": "60套/件", "supid": "", "producer": "新兴县厚德五金塑料制品有限公司", "makedate": null, "batchno": "20190601", "mbatchno": "", "expireddate": null, "amount": null, "piamount": null, "basicunit": "套", "checkindate": null, "putindate": null, "lrid": 19, "warehousemanid": "001", "warehousemanname": "sys02"}
--------------------
2020-10-14 17:40:01
FieldError("Cannot resolve keyword 'stuffkind' into field. Choices are: amount, autoid, batchno, checkindate, content, cunit, expireddate, impurity, lrid, makedate, mbatchno, package, paperno, papertype, piamount, pidate, position, pplid, price, producer, rdensity, sciid, spec, srid, status, stuffid, stuffname, stufftype, supid, supname, unit, water")
Traceback (most recent call last):
  File "D:\Anaconda3\envs\py3.8.5\lib\site-packages\django\db\models\sql\query.py", line 1863, in add_fields
    join_info = self.setup_joins(name.split(LOOKUP_SEP), opts, alias, allow_many=allow_m2m)
  File "D:\Anaconda3\envs\py3.8.5\lib\site-packages\django\db\models\sql\query.py", line 1565, in setup_joins
    path, final_field, targets, rest = self.names_to_path(
  File "D:\Anaconda3\envs\py3.8.5\lib\site-packages\django\db\models\sql\query.py", line 1481, in names_to_path
    raise FieldError("Cannot resolve keyword '%s' into field. "
django.core.exceptions.FieldError: Cannot resolve keyword 'stuffkind' into field. Choices are: amount, autoid, batchno, checkindate, content, cunit, expireddate, impurity, lrid, makedate, mbatchno, package, paperno, papertype, piamount, pidate, position, pplid, price, producer, rdensity, sciid, spec, srid, status, stuffid, stuffname, stufftype, supid, supname, unit, water

During handling of the above exception, another exception occurred:

Traceback (most recent call last):
  File "D:\pyproject\gmpsystem\warehouse\models\warehousemodel.py", line 362, in get_stuffcheckinlist
    return res.values(*args)
  File "D:\Anaconda3\envs\py3.8.5\lib\site-packages\django\db\models\query.py", line 841, in values
    clone = self._values(*fields, **expressions)
  File "D:\Anaconda3\envs\py3.8.5\lib\site-packages\django\db\models\query.py", line 836, in _values
    clone.query.set_values(fields)
  File "D:\Anaconda3\envs\py3.8.5\lib\site-packages\django\db\models\sql\query.py", line 2172, in set_values
    self.add_fields(field_names, True)
  File "D:\Anaconda3\envs\py3.8.5\lib\site-packages\django\db\models\sql\query.py", line 1885, in add_fields
    raise FieldError("Cannot resolve keyword %r into field. "
django.core.exceptions.FieldError: Cannot resolve keyword 'stuffkind' into field. Choices are: amount, autoid, batchno, checkindate, content, cunit, expireddate, impurity, lrid, makedate, mbatchno, package, paperno, papertype, piamount, pidate, position, pplid, price, producer, rdensity, sciid, spec, srid, status, stuffid, stuffname, stufftype, supid, supname, unit, water

获取进货登记的物料信息时出错
autoid
args=["lrid", "stuffid", "stuffname", "stufftype", "stuffkind", "batchno", "mbatchno", "spec", "package", "piamount", "amount", "basicunit", "makedate", "putindate", "expireddate", "nextcheckdate", "supid", "supname", "producer", "content", "cunit", "water", "rdensity", "impurity", "warehousemanid", "warehousemanname"]
kwargs={"amount__gt": 0}
--------------------