
2020-09-15 08:41:46
FieldError("Cannot resolve keyword 'p' into field. Choices are: amount, autoid, batchno, dppid, drawdate, drawerid, drawername, flag, invaliddate, makedate, ppid, prid, qadate, qaid, qaname, regdate, registerid, registername, status, unit, warehousedate, warehouseid, warehousemanid, warehousemanname, warehousename")
Traceback (most recent call last):
  File "D:\Anaconda3\envs\py3.8.5\lib\site-packages\django\db\models\sql\query.py", line 1863, in add_fields
    join_info = self.setup_joins(name.split(LOOKUP_SEP), opts, alias, allow_many=allow_m2m)
  File "D:\Anaconda3\envs\py3.8.5\lib\site-packages\django\db\models\sql\query.py", line 1565, in setup_joins
    path, final_field, targets, rest = self.names_to_path(
  File "D:\Anaconda3\envs\py3.8.5\lib\site-packages\django\db\models\sql\query.py", line 1481, in names_to_path
    raise FieldError("Cannot resolve keyword '%s' into field. "
django.core.exceptions.FieldError: Cannot resolve keyword 'p' into field. Choices are: amount, autoid, batchno, dppid, drawdate, drawerid, drawername, flag, invaliddate, makedate, ppid, prid, qadate, qaid, qaname, regdate, registerid, registername, status, unit, warehousedate, warehouseid, warehousemanid, warehousemanname, warehousename

During handling of the above exception, another exception occurred:

Traceback (most recent call last):
  File "D:\pyproject\gmpsystem\product\models\productmodel.py", line 157, in get_oddmentdrawnotes
    return res.values_list(*args, flat=flat)
  File "D:\Anaconda3\envs\py3.8.5\lib\site-packages\django\db\models\query.py", line 868, in values_list
    clone = self._values(*_fields, **expressions)
  File "D:\Anaconda3\envs\py3.8.5\lib\site-packages\django\db\models\query.py", line 836, in _values
    clone.query.set_values(fields)
  File "D:\Anaconda3\envs\py3.8.5\lib\site-packages\django\db\models\sql\query.py", line 2172, in set_values
    self.add_fields(field_names, True)
  File "D:\Anaconda3\envs\py3.8.5\lib\site-packages\django\db\models\sql\query.py", line 1885, in add_fields
    raise FieldError("Cannot resolve keyword %r into field. "
django.core.exceptions.FieldError: Cannot resolve keyword 'p' into field. Choices are: amount, autoid, batchno, dppid, drawdate, drawerid, drawername, flag, invaliddate, makedate, ppid, prid, qadate, qaid, qaname, regdate, registerid, registername, status, unit, warehousedate, warehouseid, warehousemanid, warehousemanname, warehousename

获取零头登记/发放时出错
p
args=["p", "i", "d", "flag"]
--------------------
2020-09-15 08:43:23
FieldError("Cannot resolve keyword 'status' into field. Choices are: autoid, chargerid, chargername, dpamount, dpdate, dpdepositorid, dpdepositorname, dpposition, dpremark, dpstatus, dpwarehousemanid, dpwarehousemanname, hxamount, oddment, packamount, piamount, piapplyerid, piapplyername, pidate, piqaid, piqaname, piremark, pistatus, pltype, position, ppid, qrflag, unittype, warehouseid, warehousemanid, warehousemanname, warehousename")
Traceback (most recent call last):
  File "D:\pyproject\gmpsystem\workshop\models\workshopmodels.py", line 37, in get_productputinnote
    res = Productputinnotes.objects.filter(**kwargs)
  File "D:\Anaconda3\envs\py3.8.5\lib\site-packages\django\db\models\manager.py", line 85, in manager_method
    return getattr(self.get_queryset(), name)(*args, **kwargs)
  File "D:\Anaconda3\envs\py3.8.5\lib\site-packages\django\db\models\query.py", line 942, in filter
    return self._filter_or_exclude(False, *args, **kwargs)
  File "D:\Anaconda3\envs\py3.8.5\lib\site-packages\django\db\models\query.py", line 962, in _filter_or_exclude
    clone._filter_or_exclude_inplace(negate, *args, **kwargs)
  File "D:\Anaconda3\envs\py3.8.5\lib\site-packages\django\db\models\query.py", line 969, in _filter_or_exclude_inplace
    self._query.add_q(Q(*args, **kwargs))
  File "D:\Anaconda3\envs\py3.8.5\lib\site-packages\django\db\models\sql\query.py", line 1358, in add_q
    clause, _ = self._add_q(q_object, self.used_aliases)
  File "D:\Anaconda3\envs\py3.8.5\lib\site-packages\django\db\models\sql\query.py", line 1377, in _add_q
    child_clause, needed_inner = self.build_filter(
  File "D:\Anaconda3\envs\py3.8.5\lib\site-packages\django\db\models\sql\query.py", line 1258, in build_filter
    lookups, parts, reffed_expression = self.solve_lookup_type(arg)
  File "D:\Anaconda3\envs\py3.8.5\lib\site-packages\django\db\models\sql\query.py", line 1084, in solve_lookup_type
    _, field, _, lookup_parts = self.names_to_path(lookup_splitted, self.get_meta())
  File "D:\Anaconda3\envs\py3.8.5\lib\site-packages\django\db\models\sql\query.py", line 1481, in names_to_path
    raise FieldError("Cannot resolve keyword '%s' into field. "
django.core.exceptions.FieldError: Cannot resolve keyword 'status' into field. Choices are: autoid, chargerid, chargername, dpamount, dpdate, dpdepositorid, dpdepositorname, dpposition, dpremark, dpstatus, dpwarehousemanid, dpwarehousemanname, hxamount, oddment, packamount, piamount, piapplyerid, piapplyername, pidate, piqaid, piqaname, piremark, pistatus, pltype, position, ppid, qrflag, unittype, warehouseid, warehousemanid, warehousemanname, warehousename

获取产品入库信息时出错
p
args=["p", "i", "d"]
kwargs={"status": 0}
--------------------
2020-09-15 08:43:54
FieldError("Cannot resolve keyword 'status' into field. Choices are: autoid, chargerid, chargername, dpamount, dpdate, dpdepositorid, dpdepositorname, dpposition, dpremark, dpstatus, dpwarehousemanid, dpwarehousemanname, hxamount, oddment, packamount, piamount, piapplyerid, piapplyername, pidate, piqaid, piqaname, piremark, pistatus, pltype, position, ppid, qrflag, unittype, warehouseid, warehousemanid, warehousemanname, warehousename")
Traceback (most recent call last):
  File "D:\pyproject\gmpsystem\workshop\models\workshopmodels.py", line 37, in get_productputinnote
    res = Productputinnotes.objects.filter(**kwargs)
  File "D:\Anaconda3\envs\py3.8.5\lib\site-packages\django\db\models\manager.py", line 85, in manager_method
    return getattr(self.get_queryset(), name)(*args, **kwargs)
  File "D:\Anaconda3\envs\py3.8.5\lib\site-packages\django\db\models\query.py", line 942, in filter
    return self._filter_or_exclude(False, *args, **kwargs)
  File "D:\Anaconda3\envs\py3.8.5\lib\site-packages\django\db\models\query.py", line 962, in _filter_or_exclude
    clone._filter_or_exclude_inplace(negate, *args, **kwargs)
  File "D:\Anaconda3\envs\py3.8.5\lib\site-packages\django\db\models\query.py", line 969, in _filter_or_exclude_inplace
    self._query.add_q(Q(*args, **kwargs))
  File "D:\Anaconda3\envs\py3.8.5\lib\site-packages\django\db\models\sql\query.py", line 1358, in add_q
    clause, _ = self._add_q(q_object, self.used_aliases)
  File "D:\Anaconda3\envs\py3.8.5\lib\site-packages\django\db\models\sql\query.py", line 1377, in _add_q
    child_clause, needed_inner = self.build_filter(
  File "D:\Anaconda3\envs\py3.8.5\lib\site-packages\django\db\models\sql\query.py", line 1258, in build_filter
    lookups, parts, reffed_expression = self.solve_lookup_type(arg)
  File "D:\Anaconda3\envs\py3.8.5\lib\site-packages\django\db\models\sql\query.py", line 1084, in solve_lookup_type
    _, field, _, lookup_parts = self.names_to_path(lookup_splitted, self.get_meta())
  File "D:\Anaconda3\envs\py3.8.5\lib\site-packages\django\db\models\sql\query.py", line 1481, in names_to_path
    raise FieldError("Cannot resolve keyword '%s' into field. "
django.core.exceptions.FieldError: Cannot resolve keyword 'status' into field. Choices are: autoid, chargerid, chargername, dpamount, dpdate, dpdepositorid, dpdepositorname, dpposition, dpremark, dpstatus, dpwarehousemanid, dpwarehousemanname, hxamount, oddment, packamount, piamount, piapplyerid, piapplyername, pidate, piqaid, piqaname, piremark, pistatus, pltype, position, ppid, qrflag, unittype, warehouseid, warehousemanid, warehousemanname, warehousename

获取产品入库信息时出错
ppid
kwargs={"status": 0}
--------------------