
2020-08-18 17:21:03
IntegrityError(1048, "Column 'StuffType' cannot be null")
Traceback (most recent call last):
  File "D:\Anaconda3\envs\lib\site-packages\django\db\backends\utils.py", line 86, in _execute
    return self.cursor.execute(sql, params)
  File "D:\Anaconda3\envs\lib\site-packages\django\db\backends\mysql\base.py", line 75, in execute
    return self.cursor.execute(query, args)
  File "D:\Anaconda3\envs\lib\site-packages\pymysql\cursors.py", line 170, in execute
    result = self._query(query)
  File "D:\Anaconda3\envs\lib\site-packages\pymysql\cursors.py", line 328, in _query
    conn.query(q)
  File "D:\Anaconda3\envs\lib\site-packages\pymysql\connections.py", line 517, in query
    self._affected_rows = self._read_query_result(unbuffered=unbuffered)
  File "D:\Anaconda3\envs\lib\site-packages\pymysql\connections.py", line 732, in _read_query_result
    result.read()
  File "D:\Anaconda3\envs\lib\site-packages\pymysql\connections.py", line 1075, in read
    first_packet = self.connection._read_packet()
  File "D:\Anaconda3\envs\lib\site-packages\pymysql\connections.py", line 684, in _read_packet
    packet.check_error()
  File "D:\Anaconda3\envs\lib\site-packages\pymysql\protocol.py", line 220, in check_error
    err.raise_mysql_exception(self._data)
  File "D:\Anaconda3\envs\lib\site-packages\pymysql\err.py", line 109, in raise_mysql_exception
    raise errorclass(errno, errval)
pymysql.err.IntegrityError: (1048, "Column 'StuffType' cannot be null")

The above exception was the direct cause of the following exception:

Traceback (most recent call last):
  File "d:\pyproject\GMPsystem\warehouse\models\warehousemodel.py", line 55, in update_productstuff
    return Productstuff.objects.create(**kwargs)
  File "D:\Anaconda3\envs\lib\site-packages\django\db\models\manager.py", line 82, in manager_method
    return getattr(self.get_queryset(), name)(*args, **kwargs)
  File "D:\Anaconda3\envs\lib\site-packages\django\db\models\query.py", line 433, in create
    obj.save(force_insert=True, using=self.db)
  File "D:\Anaconda3\envs\lib\site-packages\django\db\models\base.py", line 746, in save
    force_update=force_update, update_fields=update_fields)
  File "D:\Anaconda3\envs\lib\site-packages\django\db\models\base.py", line 784, in save_base
    force_update, using, update_fields,
  File "D:\Anaconda3\envs\lib\site-packages\django\db\models\base.py", line 887, in _save_table
    results = self._do_insert(cls._base_manager, using, fields, returning_fields, raw)
  File "D:\Anaconda3\envs\lib\site-packages\django\db\models\base.py", line 926, in _do_insert
    using=using, raw=raw,
  File "D:\Anaconda3\envs\lib\site-packages\django\db\models\manager.py", line 82, in manager_method
    return getattr(self.get_queryset(), name)(*args, **kwargs)
  File "D:\Anaconda3\envs\lib\site-packages\django\db\models\query.py", line 1204, in _insert
    return query.get_compiler(using=using).execute_sql(returning_fields)
  File "D:\Anaconda3\envs\lib\site-packages\django\db\models\sql\compiler.py", line 1391, in execute_sql
    cursor.execute(sql, params)
  File "D:\Anaconda3\envs\lib\site-packages\django\db\backends\utils.py", line 100, in execute
    return super().execute(sql, params)
  File "D:\Anaconda3\envs\lib\site-packages\django\db\backends\utils.py", line 68, in execute
    return self._execute_with_wrappers(sql, params, many=False, executor=self._execute)
  File "D:\Anaconda3\envs\lib\site-packages\django\db\backends\utils.py", line 77, in _execute_with_wrappers
    return executor(sql, params, many, context)
  File "D:\Anaconda3\envs\lib\site-packages\django\db\backends\utils.py", line 86, in _execute
    return self.cursor.execute(sql, params)
  File "D:\Anaconda3\envs\lib\site-packages\django\db\utils.py", line 90, in __exit__
    raise dj_exc_value.with_traceback(traceback) from exc_value
  File "D:\Anaconda3\envs\lib\site-packages\django\db\backends\utils.py", line 86, in _execute
    return self.cursor.execute(sql, params)
  File "D:\Anaconda3\envs\lib\site-packages\django\db\backends\mysql\base.py", line 75, in execute
    return self.cursor.execute(query, args)
  File "D:\Anaconda3\envs\lib\site-packages\pymysql\cursors.py", line 170, in execute
    result = self._query(query)
  File "D:\Anaconda3\envs\lib\site-packages\pymysql\cursors.py", line 328, in _query
    conn.query(q)
  File "D:\Anaconda3\envs\lib\site-packages\pymysql\connections.py", line 517, in query
    self._affected_rows = self._read_query_result(unbuffered=unbuffered)
  File "D:\Anaconda3\envs\lib\site-packages\pymysql\connections.py", line 732, in _read_query_result
    result.read()
  File "D:\Anaconda3\envs\lib\site-packages\pymysql\connections.py", line 1075, in read
    first_packet = self.connection._read_packet()
  File "D:\Anaconda3\envs\lib\site-packages\pymysql\connections.py", line 684, in _read_packet
    packet.check_error()
  File "D:\Anaconda3\envs\lib\site-packages\pymysql\protocol.py", line 220, in check_error
    err.raise_mysql_exception(self._data)
  File "D:\Anaconda3\envs\lib\site-packages\pymysql\err.py", line 109, in raise_mysql_exception
    raise errorclass(errno, errval)
django.db.utils.IntegrityError: (1048, "Column 'StuffType' cannot be null")

更新产品物料出错
kwargs={"srid": "1824", "presamount": null, "presunit": "ml", "pracamount": null, "pracunit": "ml", "drawamount": null, "drawunit": "ml", "precision": 0, "sdpid": 6808, "ppid": 36}
--------------------
2020-08-18 17:23:59
IntegrityError(1048, "Column 'StuffType' cannot be null")
Traceback (most recent call last):
  File "D:\Anaconda3\envs\lib\site-packages\django\db\backends\utils.py", line 86, in _execute
    return self.cursor.execute(sql, params)
  File "D:\Anaconda3\envs\lib\site-packages\django\db\backends\mysql\base.py", line 75, in execute
    return self.cursor.execute(query, args)
  File "D:\Anaconda3\envs\lib\site-packages\pymysql\cursors.py", line 170, in execute
    result = self._query(query)
  File "D:\Anaconda3\envs\lib\site-packages\pymysql\cursors.py", line 328, in _query
    conn.query(q)
  File "D:\Anaconda3\envs\lib\site-packages\pymysql\connections.py", line 517, in query
    self._affected_rows = self._read_query_result(unbuffered=unbuffered)
  File "D:\Anaconda3\envs\lib\site-packages\pymysql\connections.py", line 732, in _read_query_result
    result.read()
  File "D:\Anaconda3\envs\lib\site-packages\pymysql\connections.py", line 1075, in read
    first_packet = self.connection._read_packet()
  File "D:\Anaconda3\envs\lib\site-packages\pymysql\connections.py", line 684, in _read_packet
    packet.check_error()
  File "D:\Anaconda3\envs\lib\site-packages\pymysql\protocol.py", line 220, in check_error
    err.raise_mysql_exception(self._data)
  File "D:\Anaconda3\envs\lib\site-packages\pymysql\err.py", line 109, in raise_mysql_exception
    raise errorclass(errno, errval)
pymysql.err.IntegrityError: (1048, "Column 'StuffType' cannot be null")

The above exception was the direct cause of the following exception:

Traceback (most recent call last):
  File "d:\pyproject\GMPsystem\warehouse\models\warehousemodel.py", line 78, in update_stuffrepository_amount
    WarehouseModel.update_productstuff(**item)
  File "d:\pyproject\GMPsystem\warehouse\models\warehousemodel.py", line 54, in update_productstuff
    return Productstuff.objects.create(**kwargs)
  File "D:\Anaconda3\envs\lib\site-packages\django\db\models\manager.py", line 82, in manager_method
    return getattr(self.get_queryset(), name)(*args, **kwargs)
  File "D:\Anaconda3\envs\lib\site-packages\django\db\models\query.py", line 433, in create
    obj.save(force_insert=True, using=self.db)
  File "D:\Anaconda3\envs\lib\site-packages\django\db\models\base.py", line 746, in save
    force_update=force_update, update_fields=update_fields)
  File "D:\Anaconda3\envs\lib\site-packages\django\db\models\base.py", line 784, in save_base
    force_update, using, update_fields,
  File "D:\Anaconda3\envs\lib\site-packages\django\db\models\base.py", line 887, in _save_table
    results = self._do_insert(cls._base_manager, using, fields, returning_fields, raw)
  File "D:\Anaconda3\envs\lib\site-packages\django\db\models\base.py", line 926, in _do_insert
    using=using, raw=raw,
  File "D:\Anaconda3\envs\lib\site-packages\django\db\models\manager.py", line 82, in manager_method
    return getattr(self.get_queryset(), name)(*args, **kwargs)
  File "D:\Anaconda3\envs\lib\site-packages\django\db\models\query.py", line 1204, in _insert
    return query.get_compiler(using=using).execute_sql(returning_fields)
  File "D:\Anaconda3\envs\lib\site-packages\django\db\models\sql\compiler.py", line 1391, in execute_sql
    cursor.execute(sql, params)
  File "D:\Anaconda3\envs\lib\site-packages\django\db\backends\utils.py", line 100, in execute
    return super().execute(sql, params)
  File "D:\Anaconda3\envs\lib\site-packages\django\db\backends\utils.py", line 68, in execute
    return self._execute_with_wrappers(sql, params, many=False, executor=self._execute)
  File "D:\Anaconda3\envs\lib\site-packages\django\db\backends\utils.py", line 77, in _execute_with_wrappers
    return executor(sql, params, many, context)
  File "D:\Anaconda3\envs\lib\site-packages\django\db\backends\utils.py", line 86, in _execute
    return self.cursor.execute(sql, params)
  File "D:\Anaconda3\envs\lib\site-packages\django\db\utils.py", line 90, in __exit__
    raise dj_exc_value.with_traceback(traceback) from exc_value
  File "D:\Anaconda3\envs\lib\site-packages\django\db\backends\utils.py", line 86, in _execute
    return self.cursor.execute(sql, params)
  File "D:\Anaconda3\envs\lib\site-packages\django\db\backends\mysql\base.py", line 75, in execute
    return self.cursor.execute(query, args)
  File "D:\Anaconda3\envs\lib\site-packages\pymysql\cursors.py", line 170, in execute
    result = self._query(query)
  File "D:\Anaconda3\envs\lib\site-packages\pymysql\cursors.py", line 328, in _query
    conn.query(q)
  File "D:\Anaconda3\envs\lib\site-packages\pymysql\connections.py", line 517, in query
    self._affected_rows = self._read_query_result(unbuffered=unbuffered)
  File "D:\Anaconda3\envs\lib\site-packages\pymysql\connections.py", line 732, in _read_query_result
    result.read()
  File "D:\Anaconda3\envs\lib\site-packages\pymysql\connections.py", line 1075, in read
    first_packet = self.connection._read_packet()
  File "D:\Anaconda3\envs\lib\site-packages\pymysql\connections.py", line 684, in _read_packet
    packet.check_error()
  File "D:\Anaconda3\envs\lib\site-packages\pymysql\protocol.py", line 220, in check_error
    err.raise_mysql_exception(self._data)
  File "D:\Anaconda3\envs\lib\site-packages\pymysql\err.py", line 109, in raise_mysql_exception
    raise errorclass(errno, errval)
django.db.utils.IntegrityError: (1048, "Column 'StuffType' cannot be null")

更新物料库存数量出错
({'srid': '1824', 'presamount': Decimal('93'), 'presunit': 'ml', 'pracamount': Decimal('108'), 'pracunit': 'ml', 'drawamount': Decimal('110'), 'drawunit': 'ml', 'precision': 0, 'sdpid': 6808, 'ppid': 36}, {'srid': '1759', 'presamount': Decimal('30.0000'), 'presunit': 'g', 'pracamount': Decimal('15.0000'), 'pracunit': 'g', 'drawamount': Decimal('15.3000'), 'drawunit': 'g', 'precision': 4, 'sdpid': 6808, 'ppid': 36})
--------------------
2020-08-18 17:25:06
IntegrityError(1048, "Column 'StuffType' cannot be null")
Traceback (most recent call last):
  File "D:\Anaconda3\envs\lib\site-packages\django\db\backends\utils.py", line 86, in _execute
    return self.cursor.execute(sql, params)
  File "D:\Anaconda3\envs\lib\site-packages\django\db\backends\mysql\base.py", line 75, in execute
    return self.cursor.execute(query, args)
  File "D:\Anaconda3\envs\lib\site-packages\pymysql\cursors.py", line 170, in execute
    result = self._query(query)
  File "D:\Anaconda3\envs\lib\site-packages\pymysql\cursors.py", line 328, in _query
    conn.query(q)
  File "D:\Anaconda3\envs\lib\site-packages\pymysql\connections.py", line 517, in query
    self._affected_rows = self._read_query_result(unbuffered=unbuffered)
  File "D:\Anaconda3\envs\lib\site-packages\pymysql\connections.py", line 732, in _read_query_result
    result.read()
  File "D:\Anaconda3\envs\lib\site-packages\pymysql\connections.py", line 1075, in read
    first_packet = self.connection._read_packet()
  File "D:\Anaconda3\envs\lib\site-packages\pymysql\connections.py", line 684, in _read_packet
    packet.check_error()
  File "D:\Anaconda3\envs\lib\site-packages\pymysql\protocol.py", line 220, in check_error
    err.raise_mysql_exception(self._data)
  File "D:\Anaconda3\envs\lib\site-packages\pymysql\err.py", line 109, in raise_mysql_exception
    raise errorclass(errno, errval)
pymysql.err.IntegrityError: (1048, "Column 'StuffType' cannot be null")

The above exception was the direct cause of the following exception:

Traceback (most recent call last):
  File "d:\pyproject\GMPsystem\warehouse\models\warehousemodel.py", line 78, in update_stuffrepository_amount
    WarehouseModel.update_productstuff(**item)
  File "d:\pyproject\GMPsystem\warehouse\models\warehousemodel.py", line 54, in update_productstuff
    return Productstuff.objects.create(**kwargs)
  File "D:\Anaconda3\envs\lib\site-packages\django\db\models\manager.py", line 82, in manager_method
    return getattr(self.get_queryset(), name)(*args, **kwargs)
  File "D:\Anaconda3\envs\lib\site-packages\django\db\models\query.py", line 433, in create
    obj.save(force_insert=True, using=self.db)
  File "D:\Anaconda3\envs\lib\site-packages\django\db\models\base.py", line 746, in save
    force_update=force_update, update_fields=update_fields)
  File "D:\Anaconda3\envs\lib\site-packages\django\db\models\base.py", line 784, in save_base
    force_update, using, update_fields,
  File "D:\Anaconda3\envs\lib\site-packages\django\db\models\base.py", line 887, in _save_table
    results = self._do_insert(cls._base_manager, using, fields, returning_fields, raw)
  File "D:\Anaconda3\envs\lib\site-packages\django\db\models\base.py", line 926, in _do_insert
    using=using, raw=raw,
  File "D:\Anaconda3\envs\lib\site-packages\django\db\models\manager.py", line 82, in manager_method
    return getattr(self.get_queryset(), name)(*args, **kwargs)
  File "D:\Anaconda3\envs\lib\site-packages\django\db\models\query.py", line 1204, in _insert
    return query.get_compiler(using=using).execute_sql(returning_fields)
  File "D:\Anaconda3\envs\lib\site-packages\django\db\models\sql\compiler.py", line 1391, in execute_sql
    cursor.execute(sql, params)
  File "D:\Anaconda3\envs\lib\site-packages\django\db\backends\utils.py", line 100, in execute
    return super().execute(sql, params)
  File "D:\Anaconda3\envs\lib\site-packages\django\db\backends\utils.py", line 68, in execute
    return self._execute_with_wrappers(sql, params, many=False, executor=self._execute)
  File "D:\Anaconda3\envs\lib\site-packages\django\db\backends\utils.py", line 77, in _execute_with_wrappers
    return executor(sql, params, many, context)
  File "D:\Anaconda3\envs\lib\site-packages\django\db\backends\utils.py", line 86, in _execute
    return self.cursor.execute(sql, params)
  File "D:\Anaconda3\envs\lib\site-packages\django\db\utils.py", line 90, in __exit__
    raise dj_exc_value.with_traceback(traceback) from exc_value
  File "D:\Anaconda3\envs\lib\site-packages\django\db\backends\utils.py", line 86, in _execute
    return self.cursor.execute(sql, params)
  File "D:\Anaconda3\envs\lib\site-packages\django\db\backends\mysql\base.py", line 75, in execute
    return self.cursor.execute(query, args)
  File "D:\Anaconda3\envs\lib\site-packages\pymysql\cursors.py", line 170, in execute
    result = self._query(query)
  File "D:\Anaconda3\envs\lib\site-packages\pymysql\cursors.py", line 328, in _query
    conn.query(q)
  File "D:\Anaconda3\envs\lib\site-packages\pymysql\connections.py", line 517, in query
    self._affected_rows = self._read_query_result(unbuffered=unbuffered)
  File "D:\Anaconda3\envs\lib\site-packages\pymysql\connections.py", line 732, in _read_query_result
    result.read()
  File "D:\Anaconda3\envs\lib\site-packages\pymysql\connections.py", line 1075, in read
    first_packet = self.connection._read_packet()
  File "D:\Anaconda3\envs\lib\site-packages\pymysql\connections.py", line 684, in _read_packet
    packet.check_error()
  File "D:\Anaconda3\envs\lib\site-packages\pymysql\protocol.py", line 220, in check_error
    err.raise_mysql_exception(self._data)
  File "D:\Anaconda3\envs\lib\site-packages\pymysql\err.py", line 109, in raise_mysql_exception
    raise errorclass(errno, errval)
django.db.utils.IntegrityError: (1048, "Column 'StuffType' cannot be null")

更新物料库存数量出错
({'srid': '1824', 'presamount': Decimal('93'), 'presunit': 'ml', 'pracamount': Decimal('108'), 'pracunit': 'ml', 'drawamount': Decimal('110'), 'drawunit': 'ml', 'precision': 0, 'sdpid': 6808, 'ppid': 36}, {'srid': '1759', 'presamount': Decimal('30.0000'), 'presunit': 'g', 'pracamount': Decimal('15.0000'), 'pracunit': 'g', 'drawamount': Decimal('15.3000'), 'drawunit': 'g', 'precision': 4, 'sdpid': 6808, 'ppid': 36})
--------------------