
2020-09-07 16:18:34
IntegrityError(1048, "Column 'ppID' cannot be null")
Traceback (most recent call last):
  File "D:\Anaconda3\envs\py3.8.5\lib\site-packages\django\db\backends\utils.py", line 84, in _execute
    return self.cursor.execute(sql, params)
  File "D:\Anaconda3\envs\py3.8.5\lib\site-packages\django\db\backends\mysql\base.py", line 74, in execute
    return self.cursor.execute(query, args)
  File "D:\Anaconda3\envs\py3.8.5\lib\site-packages\pymysql\cursors.py", line 163, in execute
    result = self._query(query)
  File "D:\Anaconda3\envs\py3.8.5\lib\site-packages\pymysql\cursors.py", line 321, in _query
    conn.query(q)
  File "D:\Anaconda3\envs\py3.8.5\lib\site-packages\pymysql\connections.py", line 505, in query
    self._affected_rows = self._read_query_result(unbuffered=unbuffered)
  File "D:\Anaconda3\envs\py3.8.5\lib\site-packages\pymysql\connections.py", line 724, in _read_query_result
    result.read()
  File "D:\Anaconda3\envs\py3.8.5\lib\site-packages\pymysql\connections.py", line 1069, in read
    first_packet = self.connection._read_packet()
  File "D:\Anaconda3\envs\py3.8.5\lib\site-packages\pymysql\connections.py", line 676, in _read_packet
    packet.raise_for_error()
  File "D:\Anaconda3\envs\py3.8.5\lib\site-packages\pymysql\protocol.py", line 223, in raise_for_error
    err.raise_mysql_exception(self._data)
  File "D:\Anaconda3\envs\py3.8.5\lib\site-packages\pymysql\err.py", line 107, in raise_mysql_exception
    raise errorclass(errno, errval)
pymysql.err.IntegrityError: (1048, "Column 'ppID' cannot be null")

The above exception was the direct cause of the following exception:

Traceback (most recent call last):
  File "D:\pyproject\gmpsystem\product\models\productmodel.py", line 204, in update_midproddrawnotes
    return Midproddrawnotes.objects.create(**kwargs)
  File "D:\Anaconda3\envs\py3.8.5\lib\site-packages\django\db\models\manager.py", line 85, in manager_method
    return getattr(self.get_queryset(), name)(*args, **kwargs)
  File "D:\Anaconda3\envs\py3.8.5\lib\site-packages\django\db\models\query.py", line 447, in create
    obj.save(force_insert=True, using=self.db)
  File "D:\Anaconda3\envs\py3.8.5\lib\site-packages\django\db\models\base.py", line 750, in save
    self.save_base(using=using, force_insert=force_insert,
  File "D:\Anaconda3\envs\py3.8.5\lib\site-packages\django\db\models\base.py", line 787, in save_base
    updated = self._save_table(
  File "D:\Anaconda3\envs\py3.8.5\lib\site-packages\django\db\models\base.py", line 892, in _save_table
    results = self._do_insert(cls._base_manager, using, fields, returning_fields, raw)
  File "D:\Anaconda3\envs\py3.8.5\lib\site-packages\django\db\models\base.py", line 930, in _do_insert
    return manager._insert(
  File "D:\Anaconda3\envs\py3.8.5\lib\site-packages\django\db\models\manager.py", line 85, in manager_method
    return getattr(self.get_queryset(), name)(*args, **kwargs)
  File "D:\Anaconda3\envs\py3.8.5\lib\site-packages\django\db\models\query.py", line 1249, in _insert
    return query.get_compiler(using=using).execute_sql(returning_fields)
  File "D:\Anaconda3\envs\py3.8.5\lib\site-packages\django\db\models\sql\compiler.py", line 1395, in execute_sql
    cursor.execute(sql, params)
  File "D:\Anaconda3\envs\py3.8.5\lib\site-packages\django\db\backends\utils.py", line 98, in execute
    return super().execute(sql, params)
  File "D:\Anaconda3\envs\py3.8.5\lib\site-packages\django\db\backends\utils.py", line 66, in execute
    return self._execute_with_wrappers(sql, params, many=False, executor=self._execute)
  File "D:\Anaconda3\envs\py3.8.5\lib\site-packages\django\db\backends\utils.py", line 75, in _execute_with_wrappers
    return executor(sql, params, many, context)
  File "D:\Anaconda3\envs\py3.8.5\lib\site-packages\django\db\backends\utils.py", line 84, in _execute
    return self.cursor.execute(sql, params)
  File "D:\Anaconda3\envs\py3.8.5\lib\site-packages\django\db\utils.py", line 90, in __exit__
    raise dj_exc_value.with_traceback(traceback) from exc_value
  File "D:\Anaconda3\envs\py3.8.5\lib\site-packages\django\db\backends\utils.py", line 84, in _execute
    return self.cursor.execute(sql, params)
  File "D:\Anaconda3\envs\py3.8.5\lib\site-packages\django\db\backends\mysql\base.py", line 74, in execute
    return self.cursor.execute(query, args)
  File "D:\Anaconda3\envs\py3.8.5\lib\site-packages\pymysql\cursors.py", line 163, in execute
    result = self._query(query)
  File "D:\Anaconda3\envs\py3.8.5\lib\site-packages\pymysql\cursors.py", line 321, in _query
    conn.query(q)
  File "D:\Anaconda3\envs\py3.8.5\lib\site-packages\pymysql\connections.py", line 505, in query
    self._affected_rows = self._read_query_result(unbuffered=unbuffered)
  File "D:\Anaconda3\envs\py3.8.5\lib\site-packages\pymysql\connections.py", line 724, in _read_query_result
    result.read()
  File "D:\Anaconda3\envs\py3.8.5\lib\site-packages\pymysql\connections.py", line 1069, in read
    first_packet = self.connection._read_packet()
  File "D:\Anaconda3\envs\py3.8.5\lib\site-packages\pymysql\connections.py", line 676, in _read_packet
    packet.raise_for_error()
  File "D:\Anaconda3\envs\py3.8.5\lib\site-packages\pymysql\protocol.py", line 223, in raise_for_error
    err.raise_mysql_exception(self._data)
  File "D:\Anaconda3\envs\py3.8.5\lib\site-packages\pymysql\err.py", line 107, in raise_mysql_exception
    raise errorclass(errno, errval)
django.db.utils.IntegrityError: (1048, "Column 'ppID' cannot be null")

更新半成品登记/发放记录出错
kwargs={"container": "2"}
--------------------
2020-09-07 16:26:32
IntegrityError(1048, "Column 'ppID' cannot be null")
Traceback (most recent call last):
  File "D:\Anaconda3\envs\py3.8.5\lib\site-packages\django\db\backends\utils.py", line 84, in _execute
    return self.cursor.execute(sql, params)
  File "D:\Anaconda3\envs\py3.8.5\lib\site-packages\django\db\backends\mysql\base.py", line 74, in execute
    return self.cursor.execute(query, args)
  File "D:\Anaconda3\envs\py3.8.5\lib\site-packages\pymysql\cursors.py", line 163, in execute
    result = self._query(query)
  File "D:\Anaconda3\envs\py3.8.5\lib\site-packages\pymysql\cursors.py", line 321, in _query
    conn.query(q)
  File "D:\Anaconda3\envs\py3.8.5\lib\site-packages\pymysql\connections.py", line 505, in query
    self._affected_rows = self._read_query_result(unbuffered=unbuffered)
  File "D:\Anaconda3\envs\py3.8.5\lib\site-packages\pymysql\connections.py", line 724, in _read_query_result
    result.read()
  File "D:\Anaconda3\envs\py3.8.5\lib\site-packages\pymysql\connections.py", line 1069, in read
    first_packet = self.connection._read_packet()
  File "D:\Anaconda3\envs\py3.8.5\lib\site-packages\pymysql\connections.py", line 676, in _read_packet
    packet.raise_for_error()
  File "D:\Anaconda3\envs\py3.8.5\lib\site-packages\pymysql\protocol.py", line 223, in raise_for_error
    err.raise_mysql_exception(self._data)
  File "D:\Anaconda3\envs\py3.8.5\lib\site-packages\pymysql\err.py", line 107, in raise_mysql_exception
    raise errorclass(errno, errval)
pymysql.err.IntegrityError: (1048, "Column 'ppID' cannot be null")

The above exception was the direct cause of the following exception:

Traceback (most recent call last):
  File "D:\pyproject\gmpsystem\product\models\productmodel.py", line 205, in update_midproddrawnotes
    return Midproddrawnotes.objects.create(**kwargs)
  File "D:\Anaconda3\envs\py3.8.5\lib\site-packages\django\db\models\manager.py", line 85, in manager_method
    return getattr(self.get_queryset(), name)(*args, **kwargs)
  File "D:\Anaconda3\envs\py3.8.5\lib\site-packages\django\db\models\query.py", line 447, in create
    obj.save(force_insert=True, using=self.db)
  File "D:\Anaconda3\envs\py3.8.5\lib\site-packages\django\db\models\base.py", line 750, in save
    self.save_base(using=using, force_insert=force_insert,
  File "D:\Anaconda3\envs\py3.8.5\lib\site-packages\django\db\models\base.py", line 787, in save_base
    updated = self._save_table(
  File "D:\Anaconda3\envs\py3.8.5\lib\site-packages\django\db\models\base.py", line 892, in _save_table
    results = self._do_insert(cls._base_manager, using, fields, returning_fields, raw)
  File "D:\Anaconda3\envs\py3.8.5\lib\site-packages\django\db\models\base.py", line 930, in _do_insert
    return manager._insert(
  File "D:\Anaconda3\envs\py3.8.5\lib\site-packages\django\db\models\manager.py", line 85, in manager_method
    return getattr(self.get_queryset(), name)(*args, **kwargs)
  File "D:\Anaconda3\envs\py3.8.5\lib\site-packages\django\db\models\query.py", line 1249, in _insert
    return query.get_compiler(using=using).execute_sql(returning_fields)
  File "D:\Anaconda3\envs\py3.8.5\lib\site-packages\django\db\models\sql\compiler.py", line 1395, in execute_sql
    cursor.execute(sql, params)
  File "D:\Anaconda3\envs\py3.8.5\lib\site-packages\django\db\backends\utils.py", line 98, in execute
    return super().execute(sql, params)
  File "D:\Anaconda3\envs\py3.8.5\lib\site-packages\django\db\backends\utils.py", line 66, in execute
    return self._execute_with_wrappers(sql, params, many=False, executor=self._execute)
  File "D:\Anaconda3\envs\py3.8.5\lib\site-packages\django\db\backends\utils.py", line 75, in _execute_with_wrappers
    return executor(sql, params, many, context)
  File "D:\Anaconda3\envs\py3.8.5\lib\site-packages\django\db\backends\utils.py", line 84, in _execute
    return self.cursor.execute(sql, params)
  File "D:\Anaconda3\envs\py3.8.5\lib\site-packages\django\db\utils.py", line 90, in __exit__
    raise dj_exc_value.with_traceback(traceback) from exc_value
  File "D:\Anaconda3\envs\py3.8.5\lib\site-packages\django\db\backends\utils.py", line 84, in _execute
    return self.cursor.execute(sql, params)
  File "D:\Anaconda3\envs\py3.8.5\lib\site-packages\django\db\backends\mysql\base.py", line 74, in execute
    return self.cursor.execute(query, args)
  File "D:\Anaconda3\envs\py3.8.5\lib\site-packages\pymysql\cursors.py", line 163, in execute
    result = self._query(query)
  File "D:\Anaconda3\envs\py3.8.5\lib\site-packages\pymysql\cursors.py", line 321, in _query
    conn.query(q)
  File "D:\Anaconda3\envs\py3.8.5\lib\site-packages\pymysql\connections.py", line 505, in query
    self._affected_rows = self._read_query_result(unbuffered=unbuffered)
  File "D:\Anaconda3\envs\py3.8.5\lib\site-packages\pymysql\connections.py", line 724, in _read_query_result
    result.read()
  File "D:\Anaconda3\envs\py3.8.5\lib\site-packages\pymysql\connections.py", line 1069, in read
    first_packet = self.connection._read_packet()
  File "D:\Anaconda3\envs\py3.8.5\lib\site-packages\pymysql\connections.py", line 676, in _read_packet
    packet.raise_for_error()
  File "D:\Anaconda3\envs\py3.8.5\lib\site-packages\pymysql\protocol.py", line 223, in raise_for_error
    err.raise_mysql_exception(self._data)
  File "D:\Anaconda3\envs\py3.8.5\lib\site-packages\pymysql\err.py", line 107, in raise_mysql_exception
    raise errorclass(errno, errval)
django.db.utils.IntegrityError: (1048, "Column 'ppID' cannot be null")

更新半成品登记/发放记录出错
kwargs={"container": "1"}
--------------------
2020-09-07 16:28:53
IntegrityError(1048, "Column 'Amount' cannot be null")
Traceback (most recent call last):
  File "D:\Anaconda3\envs\py3.8.5\lib\site-packages\django\db\backends\utils.py", line 84, in _execute
    return self.cursor.execute(sql, params)
  File "D:\Anaconda3\envs\py3.8.5\lib\site-packages\django\db\backends\mysql\base.py", line 74, in execute
    return self.cursor.execute(query, args)
  File "D:\Anaconda3\envs\py3.8.5\lib\site-packages\pymysql\cursors.py", line 163, in execute
    result = self._query(query)
  File "D:\Anaconda3\envs\py3.8.5\lib\site-packages\pymysql\cursors.py", line 321, in _query
    conn.query(q)
  File "D:\Anaconda3\envs\py3.8.5\lib\site-packages\pymysql\connections.py", line 505, in query
    self._affected_rows = self._read_query_result(unbuffered=unbuffered)
  File "D:\Anaconda3\envs\py3.8.5\lib\site-packages\pymysql\connections.py", line 724, in _read_query_result
    result.read()
  File "D:\Anaconda3\envs\py3.8.5\lib\site-packages\pymysql\connections.py", line 1069, in read
    first_packet = self.connection._read_packet()
  File "D:\Anaconda3\envs\py3.8.5\lib\site-packages\pymysql\connections.py", line 676, in _read_packet
    packet.raise_for_error()
  File "D:\Anaconda3\envs\py3.8.5\lib\site-packages\pymysql\protocol.py", line 223, in raise_for_error
    err.raise_mysql_exception(self._data)
  File "D:\Anaconda3\envs\py3.8.5\lib\site-packages\pymysql\err.py", line 107, in raise_mysql_exception
    raise errorclass(errno, errval)
pymysql.err.IntegrityError: (1048, "Column 'Amount' cannot be null")

The above exception was the direct cause of the following exception:

Traceback (most recent call last):
  File "D:\pyproject\gmpsystem\product\models\productmodel.py", line 205, in update_midproddrawnotes
    return Midproddrawnotes.objects.create(**kwargs)
  File "D:\Anaconda3\envs\py3.8.5\lib\site-packages\django\db\models\manager.py", line 85, in manager_method
    return getattr(self.get_queryset(), name)(*args, **kwargs)
  File "D:\Anaconda3\envs\py3.8.5\lib\site-packages\django\db\models\query.py", line 447, in create
    obj.save(force_insert=True, using=self.db)
  File "D:\Anaconda3\envs\py3.8.5\lib\site-packages\django\db\models\base.py", line 750, in save
    self.save_base(using=using, force_insert=force_insert,
  File "D:\Anaconda3\envs\py3.8.5\lib\site-packages\django\db\models\base.py", line 787, in save_base
    updated = self._save_table(
  File "D:\Anaconda3\envs\py3.8.5\lib\site-packages\django\db\models\base.py", line 892, in _save_table
    results = self._do_insert(cls._base_manager, using, fields, returning_fields, raw)
  File "D:\Anaconda3\envs\py3.8.5\lib\site-packages\django\db\models\base.py", line 930, in _do_insert
    return manager._insert(
  File "D:\Anaconda3\envs\py3.8.5\lib\site-packages\django\db\models\manager.py", line 85, in manager_method
    return getattr(self.get_queryset(), name)(*args, **kwargs)
  File "D:\Anaconda3\envs\py3.8.5\lib\site-packages\django\db\models\query.py", line 1249, in _insert
    return query.get_compiler(using=using).execute_sql(returning_fields)
  File "D:\Anaconda3\envs\py3.8.5\lib\site-packages\django\db\models\sql\compiler.py", line 1395, in execute_sql
    cursor.execute(sql, params)
  File "D:\Anaconda3\envs\py3.8.5\lib\site-packages\django\db\backends\utils.py", line 98, in execute
    return super().execute(sql, params)
  File "D:\Anaconda3\envs\py3.8.5\lib\site-packages\django\db\backends\utils.py", line 66, in execute
    return self._execute_with_wrappers(sql, params, many=False, executor=self._execute)
  File "D:\Anaconda3\envs\py3.8.5\lib\site-packages\django\db\backends\utils.py", line 75, in _execute_with_wrappers
    return executor(sql, params, many, context)
  File "D:\Anaconda3\envs\py3.8.5\lib\site-packages\django\db\backends\utils.py", line 84, in _execute
    return self.cursor.execute(sql, params)
  File "D:\Anaconda3\envs\py3.8.5\lib\site-packages\django\db\utils.py", line 90, in __exit__
    raise dj_exc_value.with_traceback(traceback) from exc_value
  File "D:\Anaconda3\envs\py3.8.5\lib\site-packages\django\db\backends\utils.py", line 84, in _execute
    return self.cursor.execute(sql, params)
  File "D:\Anaconda3\envs\py3.8.5\lib\site-packages\django\db\backends\mysql\base.py", line 74, in execute
    return self.cursor.execute(query, args)
  File "D:\Anaconda3\envs\py3.8.5\lib\site-packages\pymysql\cursors.py", line 163, in execute
    result = self._query(query)
  File "D:\Anaconda3\envs\py3.8.5\lib\site-packages\pymysql\cursors.py", line 321, in _query
    conn.query(q)
  File "D:\Anaconda3\envs\py3.8.5\lib\site-packages\pymysql\connections.py", line 505, in query
    self._affected_rows = self._read_query_result(unbuffered=unbuffered)
  File "D:\Anaconda3\envs\py3.8.5\lib\site-packages\pymysql\connections.py", line 724, in _read_query_result
    result.read()
  File "D:\Anaconda3\envs\py3.8.5\lib\site-packages\pymysql\connections.py", line 1069, in read
    first_packet = self.connection._read_packet()
  File "D:\Anaconda3\envs\py3.8.5\lib\site-packages\pymysql\connections.py", line 676, in _read_packet
    packet.raise_for_error()
  File "D:\Anaconda3\envs\py3.8.5\lib\site-packages\pymysql\protocol.py", line 223, in raise_for_error
    err.raise_mysql_exception(self._data)
  File "D:\Anaconda3\envs\py3.8.5\lib\site-packages\pymysql\err.py", line 107, in raise_mysql_exception
    raise errorclass(errno, errval)
django.db.utils.IntegrityError: (1048, "Column 'Amount' cannot be null")

更新半成品登记/发放记录出错
kwargs={"container": "1", "ppid": 28}
--------------------